Workbook

Sheet Tabla anual
A1: Equipos | B1: Puntos | C1: Participante | D1: Cantidad | E1: Participante | F1: Velocidad
A2: 1 | B2: 4 | C2: 1 | D2: 4 | E2: 1 | F2: 4
A3: 2 | B3: 3 | C3: 2 | D3: 3 | E3: 2 | F3: 3
A4: 3 | B4: 2 | C4: 3 | D4: 2 | E4: 3 | F4: 2
C5: Media | D5: 1 | E5: Media | F5: 1
A7: Tabla Semanal
A8: Jugadores | B8: 45992 | C8: 45993 | D8: 45994 | E8: 45995 | F8: 46023 | G8: 46024 | H8: 46025 | I8: 46026 | J8: 46054 | K8: Total
A9: Abi | B9: =IFERROR( VLOOKUP($A9, '112'!$B$14:$I$24, 8, FALSE), 0 ) -> 0 | C9: =IFERROR( VLOOKUP($A9, '212'!$B$14:$I$24, 8, FALSE), 0 ) -> 3 | D9: =IFERROR( VLOOKUP($A9, '312'!$B$14:$I$24, 8, FALSE), 0 ) -> 3 | E9: =IFERROR( VLOOKUP($A9, '412'!$B$14:$I$24, 8, FALSE), 0 ) -> 3 | F9: =IFERROR( VLOOKUP($A9, '11'!$B$14:$I$24, 8, FALSE), 0 ) -> 12 | G9: =IFERROR( VLOOKUP($A9, '21'!$B$14:$I$24, 8, FALSE), 0 ) -> 5 | H9: =IFERROR( VLOOKUP($A9, '31'!$B$14:$I$24, 8, FALSE), 0 ) -> 3 | I9: =IFERROR( VLOOKUP($A9, '41'!$B$14:$I$24, 8, FALSE), 0 ) -> 2 | J9: =IFERROR( VLOOKUP($A9, '12'!$B$14:$I$24, 8, FALSE), 0 ) -> 2 | K9: =sum(B9:J9) -> 33
A10: Chiqui | B10: =IFERROR( VLOOKUP($A10, '112'!$B$14:$I$24, 8, FALSE), 0 ) -> 4 | C10: =IFERROR( VLOOKUP($A10, '212'!$B$14:$I$24, 8, FALSE), 0 ) -> 3 | D10: =IFERROR( VLOOKUP($A10, '312'!$B$14:$I$24, 8, FALSE), 0 ) -> 4 | E10: =IFERROR( VLOOKUP($A10, '412'!$B$14:$I$24, 8, FALSE), 0 ) -> 3 | F10: =IFERROR( VLOOKUP($A10, '11'!$B$14:$I$24, 8, FALSE), 0 ) -> 12 | G10: =IFERROR( VLOOKUP($A10, '21'!$B$14:$I$24, 8, FALSE), 0 ) -> 6 | H10: =IFERROR( VLOOKUP($A10, '31'!$B$14:$I$24, 8, FALSE), 0 ) -> 5 | I10: =IFERROR( VLOOKUP($A10, '41'!$B$14:$I$24, 8, FALSE), 0 ) -> 6 | J10: =IFERROR( VLOOKUP($A10, '12'!$B$14:$I$24, 8, FALSE), 0 ) -> 8 | K10: =sum(B10:J10) -> 51
A11: Estela | B11: =IFERROR( VLOOKUP($A11, '112'!$B$14:$I$24, 8, FALSE), 0 ) -> 2 | C11: =IFERROR( VLOOKUP($A11, '212'!$B$14:$I$24, 8, FALSE), 0 ) -> 2 | D11: =IFERROR( VLOOKUP($A11, '312'!$B$14:$I$24, 8, FALSE), 0 ) -> 4 | E11: =IFERROR( VLOOKUP($A11, '412'!$B$14:$I$24, 8, FALSE), 0 ) -> 4 | F11: =IFERROR( VLOOKUP($A11, '11'!$B$14:$I$24, 8, FALSE), 0 ) -> 3 | G11: =IFERROR( VLOOKUP($A11, '21'!$B$14:$I$24, 8, FALSE), 0 ) -> 4 | H11: =IFERROR( VLOOKUP($A11, '31'!$B$14:$I$24, 8, FALSE), 0 ) -> 3 | I11: =IFERROR( VLOOKUP($A11, '41'!$B$14:$I$24, 8, FALSE), 0 ) -> 7 | J11: =IFERROR( VLOOKUP($A11, '12'!$B$14:$I$24, 8, FALSE), 0 ) -> 8 | K11: =sum(B11:J11) -> 37
A12: Facu | B12: =IFERROR( VLOOKUP($A12, '112'!$B$14:$I$24, 8, FALSE), 0 ) -> 12 | C12: =IFERROR( VLOOKUP($A12, '212'!$B$14:$I$24, 8, FALSE), 0 ) -> 4 | D12: =IFERROR( VLOOKUP($A12, '312'!$B$14:$I$24, 8, FALSE), 0 ) -> 6 | E12: =IFERROR( VLOOKUP($A12, '412'!$B$14:$I$24, 8, FALSE), 0 ) -> 7 | F12: =IFERROR( VLOOKUP($A12, '11'!$B$14:$I$24, 8, FALSE), 0 ) -> 0 | G12: =IFERROR( VLOOKUP($A12, '21'!$B$14:$I$24, 8, FALSE), 0 ) -> 3 | H12: =IFERROR( VLOOKUP($A12, '31'!$B$14:$I$24, 8, FALSE), 0 ) -> 2 | I12: =IFERROR( VLOOKUP($A12, '41'!$B$14:$I$24, 8, FALSE), 0 ) -> 2 | J12: =IFERROR( VLOOKUP($A12, '12'!$B$14:$I$24, 8, FALSE), 0 ) -> 11 | K12: =sum(B12:J12) -> 47
A13: Gio | B13: =IFERROR( VLOOKUP($A13, '112'!$B$14:$I$24, 8, FALSE), 0 ) -> 4 | C13: =IFERROR( VLOOKUP($A13, '212'!$B$14:$I$24, 8, FALSE), 0 ) -> 4 | D13: =IFERROR( VLOOKUP($A13, '312'!$B$14:$I$24, 8, FALSE), 0 ) -> 2 | E13: =IFERROR( VLOOKUP($A13, '412'!$B$14:$I$24, 8, FALSE), 0 ) -> 4 | F13: =IFERROR( VLOOKUP($A13, '11'!$B$14:$I$24, 8, FALSE), 0 ) -> 3 | G13: =IFERROR( VLOOKUP($A13, '21'!$B$14:$I$24, 8, FALSE), 0 ) -> 6 | H13: =IFERROR( VLOOKUP($A13, '31'!$B$14:$I$24, 8, FALSE), 0 ) -> 7 | I13: =IFERROR( VLOOKUP($A13, '41'!$B$14:$I$24, 8, FALSE), 0 ) -> 7 | J13: =IFERROR( VLOOKUP($A13, '12'!$B$14:$I$24, 8, FALSE), 0 ) -> 4 | K13: =sum(B13:J13) -> 41
A14: Lu | B14: =IFERROR( VLOOKUP($A14, '112'!$B$14:$I$24, 8, FALSE), 0 ) -> 6 | C14: =IFERROR( VLOOKUP($A14, '212'!$B$14:$I$24, 8, FALSE), 0 ) -> 3 | D14: =IFERROR( VLOOKUP($A14, '312'!$B$14:$I$24, 8, FALSE), 0 ) -> 3 | E14: =IFERROR( VLOOKUP($A14, '412'!$B$14:$I$24, 8, FALSE), 0 ) -> 5 | F14: =IFERROR( VLOOKUP($A14, '11'!$B$14:$I$24, 8, FALSE), 0 ) -> 3 | G14: =IFERROR( VLOOKUP($A14, '21'!$B$14:$I$24, 8, FALSE), 0 ) -> 7 | H14: =IFERROR( VLOOKUP($A14, '31'!$B$14:$I$24, 8, FALSE), 0 ) -> 7 | I14: =IFERROR( VLOOKUP($A14, '41'!$B$14:$I$24, 8, FALSE), 0 ) -> 7 | J14: =IFERROR( VLOOKUP($A14, '12'!$B$14:$I$24, 8, FALSE), 0 ) -> 4 | K14: =sum(B14:J14) -> 45
A15: Maru C | B15: =IFERROR( VLOOKUP($A15, '112'!$B$14:$I$24, 8, FALSE), 0 ) -> 3 | C15: =IFERROR( VLOOKUP($A15, '212'!$B$14:$I$24, 8, FALSE), 0 ) -> 12 | D15: =IFERROR( VLOOKUP($A15, '312'!$B$14:$I$24, 8, FALSE), 0 ) -> 2 | E15: =IFERROR( VLOOKUP($A15, '412'!$B$14:$I$24, 8, FALSE), 0 ) -> 6 | F15: =IFERROR( VLOOKUP($A15, '11'!$B$14:$I$24, 8, FALSE), 0 ) -> 4 | G15: =IFERROR( VLOOKUP($A15, '21'!$B$14:$I$24, 8, FALSE), 0 ) -> 2 | H15: =IFERROR( VLOOKUP($A15, '31'!$B$14:$I$24, 8, FALSE), 0 ) -> 2 | I15: =IFERROR( VLOOKUP($A15, '41'!$B$14:$I$24, 8, FALSE), 0 ) -> 3 | J15: =IFERROR( VLOOKUP($A15, '12'!$B$14:$I$24, 8, FALSE), 0 ) -> 3 | K15: =sum(B15:J15) -> 37
A16: Maru M | B16: =IFERROR( VLOOKUP($A16, '112'!$B$14:$I$24, 8, FALSE), 0 ) -> 8 | C16: =IFERROR( VLOOKUP($A16, '212'!$B$14:$I$24, 8, FALSE), 0 ) -> 2 | D16: =IFERROR( VLOOKUP($A16, '312'!$B$14:$I$24, 8, FALSE), 0 ) -> 3 | E16: =IFERROR( VLOOKUP($A16, '412'!$B$14:$I$24, 8, FALSE), 0 ) -> 6 | F16: =IFERROR( VLOOKUP($A16, '11'!$B$14:$I$24, 8, FALSE), 0 ) -> 7 | G16: =IFERROR( VLOOKUP($A16, '21'!$B$14:$I$24, 8, FALSE), 0 ) -> 7 | H16: =IFERROR( VLOOKUP($A16, '31'!$B$14:$I$24, 8, FALSE), 0 ) -> 5 | I16: =IFERROR( VLOOKUP($A16, '41'!$B$14:$I$24, 8, FALSE), 0 ) -> 10 | J16: =IFERROR( VLOOKUP($A16, '12'!$B$14:$I$24, 8, FALSE), 0 ) -> 3 | K16: =sum(B16:J16) -> 51
A17: Nico | B17: =IFERROR( VLOOKUP($A17, '112'!$B$14:$I$24, 8, FALSE), 0 ) -> 4 | C17: =IFERROR( VLOOKUP($A17, '212'!$B$14:$I$24, 8, FALSE), 0 ) -> 8 | D17: =IFERROR( VLOOKUP($A17, '312'!$B$14:$I$24, 8, FALSE), 0 ) -> 3 | E17: =IFERROR( VLOOKUP($A17, '412'!$B$14:$I$24, 8, FALSE), 0 ) -> 8 | F17: =IFERROR( VLOOKUP($A17, '11'!$B$14:$I$24, 8, FALSE), 0 ) -> 5 | G17: =IFERROR( VLOOKUP($A17, '21'!$B$14:$I$24, 8, FALSE), 0 ) -> 9 | H17: =IFERROR( VLOOKUP($A17, '31'!$B$14:$I$24, 8, FALSE), 0 ) -> 2 | I17: =IFERROR( VLOOKUP($A17, '41'!$B$14:$I$24, 8, FALSE), 0 ) -> 4 | J17: =IFERROR( VLOOKUP($A17, '12'!$B$14:$I$24, 8, FALSE), 0 ) -> 11 | K17: =sum(B17:J17) -> 54
A18: Samy | B18: =IFERROR( VLOOKUP($A18, '112'!$B$14:$I$24, 8, FALSE), 0 ) -> 5 | C18: =IFERROR( VLOOKUP($A18, '212'!$B$14:$I$24, 8, FALSE), 0 ) -> 4 | D18: =IFERROR( VLOOKUP($A18, '312'!$B$14:$I$24, 8, FALSE), 0 ) -> 8 | E18: =IFERROR( VLOOKUP($A18, '412'!$B$14:$I$24, 8, FALSE), 0 ) -> 3 | F18: =IFERROR( VLOOKUP($A18, '11'!$B$14:$I$24, 8, FALSE), 0 ) -> 3 | G18: =IFERROR( VLOOKUP($A18, '21'!$B$14:$I$24, 8, FALSE), 0 ) -> 6 | H18: =IFERROR( VLOOKUP($A18, '31'!$B$14:$I$24, 8, FALSE), 0 ) -> 5 | I18: =IFERROR( VLOOKUP($A18, '41'!$B$14:$I$24, 8, FALSE), 0 ) -> 5 | J18: =IFERROR( VLOOKUP($A18, '12'!$B$14:$I$24, 8, FALSE), 0 ) -> 4 | K18: =sum(B18:J18) -> 43
A19: Vicky | B19: =IFERROR( VLOOKUP($A19, '112'!$B$14:$I$24, 8, FALSE), 0 ) -> 7 | C19: =IFERROR( VLOOKUP($A19, '212'!$B$14:$I$24, 8, FALSE), 0 ) -> 7 | D19: =IFERROR( VLOOKUP($A19, '312'!$B$14:$I$24, 8, FALSE), 0 ) -> 4 | E19: =IFERROR( VLOOKUP($A19, '412'!$B$14:$I$24, 8, FALSE), 0 ) -> 11 | F19: =IFERROR( VLOOKUP($A19, '11'!$B$14:$I$24, 8, FALSE), 0 ) -> 6 | G19: =IFERROR( VLOOKUP($A19, '21'!$B$14:$I$24, 8, FALSE), 0 ) -> 10 | H19: =IFERROR( VLOOKUP($A19, '31'!$B$14:$I$24, 8, FALSE), 0 ) -> 4 | I19: =IFERROR( VLOOKUP($A19, '41'!$B$14:$I$24, 8, FALSE), 0 ) -> 8 | J19: =IFERROR( VLOOKUP($A19, '12'!$B$14:$I$24, 8, FALSE), 0 ) -> 7 | K19: =sum(B19:J19) -> 64
A23: Tabla anual
A24: Jugador | B24: Total
A25: =IFERROR(__xludf.DUMMYFUNCTION("SORT( FILTER({A9:A19,K9:K19}, K9:K19<>""""), 2, FALSE )"),"Vicky") -> Vicky | B25: =IFERROR(__xludf.DUMMYFUNCTION("""COMPUTED_VALUE"""),64.0) -> 64 | C25: =LET( fila, MATCH($A25, $A$9:$A$19, 0), col_total, MATCH("Total", $B$8:$AB$8, 0), ult_sem, col_total-1, actual, INDEX($B$9:$AB$19, fila, ult_sem), anterior, INDEX($B$9:$AB$19, fila, ult_sem-1), IF(actual>anterior, "🔼", IF(actual<anterior, "🔻", "")) ) -> 🔻
A26: =IFERROR(__xludf.DUMMYFUNCTION("""COMPUTED_VALUE"""),"Nico") -> Nico | B26: =IFERROR(__xludf.DUMMYFUNCTION("""COMPUTED_VALUE"""),54.0) -> 54 | C26: =LET( fila, MATCH($A26, $A$9:$A$19, 0), col_total, MATCH("Total", $B$8:$AB$8, 0), ult_sem, col_total-1, actual, INDEX($B$9:$AB$19, fila, ult_sem), anterior, INDEX($B$9:$AB$19, fila, ult_sem-1), IF(actual>anterior, "🔼", IF(actual<anterior, "🔻", "")) ) -> 🔼
A27: =IFERROR(__xludf.DUMMYFUNCTION("""COMPUTED_VALUE"""),"Chiqui") -> Chiqui | B27: =IFERROR(__xludf.DUMMYFUNCTION("""COMPUTED_VALUE"""),51.0) -> 51 | C27: =LET( fila, MATCH($A27, $A$9:$A$19, 0), col_total, MATCH("Total", $B$8:$AB$8, 0), ult_sem, col_total-1, actual, INDEX($B$9:$AB$19, fila, ult_sem), anterior, INDEX($B$9:$AB$19, fila, ult_sem-1), IF(actual>anterior, "🔼", IF(actual<anterior, "🔻", "")) ) -> 🔼
A28: =IFERROR(__xludf.DUMMYFUNCTION("""COMPUTED_VALUE"""),"Maru M") -> Maru M | B28: =IFERROR(__xludf.DUMMYFUNCTION("""COMPUTED_VALUE"""),51.0) -> 51 | C28: =LET( fila, MATCH($A28, $A$9:$A$19, 0), col_total, MATCH("Total", $B$8:$AB$8, 0), ult_sem, col_total-1, actual, INDEX($B$9:$AB$19, fila, ult_sem), anterior, INDEX($B$9:$AB$19, fila, ult_sem-1), IF(actual>anterior, "🔼", IF(actual<anterior, "🔻", "")) ) -> 🔻
A29: =IFERROR(__xludf.DUMMYFUNCTION("""COMPUTED_VALUE"""),"Facu") -> Facu | B29: =IFERROR(__xludf.DUMMYFUNCTION("""COMPUTED_VALUE"""),47.0) -> 47 | C29: =LET( fila, MATCH($A29, $A$9:$A$19, 0), col_total, MATCH("Total", $B$8:$AB$8, 0), ult_sem, col_total-1, actual, INDEX($B$9:$AB$19, fila, ult_sem), anterior, INDEX($B$9:$AB$19, fila, ult_sem-1), IF(actual>anterior, "🔼", IF(actual<anterior, "🔻", "")) ) -> 🔼
A30: =IFERROR(__xludf.DUMMYFUNCTION("""COMPUTED_VALUE"""),"Lu") -> Lu | B30: =IFERROR(__xludf.DUMMYFUNCTION("""COMPUTED_VALUE"""),45.0) -> 45 | C30: =LET( fila, MATCH($A30, $A$9:$A$19, 0), col_total, MATCH("Total", $B$8:$AB$8, 0), ult_sem, col_total-1, actual, INDEX($B$9:$AB$19, fila, ult_sem), anterior, INDEX($B$9:$AB$19, fila, ult_sem-1), IF(actual>anterior, "🔼", IF(actual<anterior, "🔻", "")) ) -> 🔻
A31: =IFERROR(__xludf.DUMMYFUNCTION("""COMPUTED_VALUE"""),"Samy") -> Samy | B31: =IFERROR(__xludf.DUMMYFUNCTION("""COMPUTED_VALUE"""),43.0) -> 43 | C31: =LET( fila, MATCH($A31, $A$9:$A$19, 0), col_total, MATCH("Total", $B$8:$AB$8, 0), ult_sem, col_total-1, actual, INDEX($B$9:$AB$19, fila, ult_sem), anterior, INDEX($B$9:$AB$19, fila, ult_sem-1), IF(actual>anterior, "🔼", IF(actual<anterior, "🔻", "")) ) -> 🔻
A32: =IFERROR(__xludf.DUMMYFUNCTION("""COMPUTED_VALUE"""),"Gio") -> Gio | B32: =IFERROR(__xludf.DUMMYFUNCTION("""COMPUTED_VALUE"""),41.0) -> 41 | C32: =LET( fila, MATCH($A32, $A$9:$A$19, 0), col_total, MATCH("Total", $B$8:$AB$8, 0), ult_sem, col_total-1, actual, INDEX($B$9:$AB$19, fila, ult_sem), anterior, INDEX($B$9:$AB$19, fila, ult_sem-1), IF(actual>anterior, "🔼", IF(actual<anterior, "🔻", "")) ) -> 🔻
A33: =IFERROR(__xludf.DUMMYFUNCTION("""COMPUTED_VALUE"""),"Estela") -> Estela | B33: =IFERROR(__xludf.DUMMYFUNCTION("""COMPUTED_VALUE"""),37.0) -> 37 | C33: =LET( fila, MATCH($A33, $A$9:$A$19, 0), col_total, MATCH("Total", $B$8:$AB$8, 0), ult_sem, col_total-1, actual, INDEX($B$9:$AB$19, fila, ult_sem), anterior, INDEX($B$9:$AB$19, fila, ult_sem-1), IF(actual>anterior, "🔼", IF(actual<anterior, "🔻", "")) ) -> 🔼
A34: =IFERROR(__xludf.DUMMYFUNCTION("""COMPUTED_VALUE"""),"Maru C") -> Maru C | B34: =IFERROR(__xludf.DUMMYFUNCTION("""COMPUTED_VALUE"""),37.0) -> 37 | C34: =LET( fila, MATCH($A34, $A$9:$A$19, 0), col_total, MATCH("Total", $B$8:$AB$8, 0), ult_sem, col_total-1, actual, INDEX($B$9:$AB$19, fila, ult_sem), anterior, INDEX($B$9:$AB$19, fila, ult_sem-1), IF(actual>anterior, "🔼", IF(actual<anterior, "🔻", "")) )
A35: =IFERROR(__xludf.DUMMYFUNCTION("""COMPUTED_VALUE"""),"Abi") -> Abi | B35: =IFERROR(__xludf.DUMMYFUNCTION("""COMPUTED_VALUE"""),33.0) -> 33 | C35: =LET( fila, MATCH($A35, $A$9:$A$19, 0), col_total, MATCH("Total", $B$8:$AB$8, 0), ult_sem, col_total-1, actual, INDEX($B$9:$AB$19, fila, ult_sem), anterior, INDEX($B$9:$AB$19, fila, ult_sem-1), IF(actual>anterior, "🔼", IF(actual<anterior, "🔻", "")) )

Sheet 112
A1: Objetivo del desafío | B1: Girar 150 Poképaradas
A2: Fecha de inicio | B2: 46000.917
A3: Fecha final oficial | B3: 46007.917
A4: Duración total (horas) | B4: =(B3-B2)*24 -> 168
A5: Ritmo oficial (giros/hora) | B5: =150/B4 -> 0.89285714
A6: Cantidad Media (cantidadxequipos)/participantes | B6: =(150*3)/10 -> 45
A8: Equipo | B8: Puesto | C8: Hora de finalización | D8: Horas totales | E8: Puntos
A9: Rojo | B9: 1 | C9: 46001.358 | D9: =(C9-$B$2)*24 -> 10.6 | E9: ='Tabla anual'!B2 -> 4
A10: Amarillo | B10: 2 | C10: 46001.586 | D10: =(C10-$B$2)*24 -> 16.066667 | E10: ='Tabla anual'!B3 -> 3
A11: Celeste | B11: 3 | C11: 46001.638 | D11: =(C11-$B$2)*24 -> 17.316667 | E11: ='Tabla anual'!B4 -> 2
A13: Posición | B13: Nombre | C13: Equipo | D13: Cantidad | E13: Plus Velocidad | F13: Puntos Equipo | G13: Puntos Cantidad | H13: Puntos Velocidad | I13: Total de Puntos
A14: 1 | B14: Facu | C14: Rojo | D14: 93 | E14: =IFERROR( FLOOR( (D14 / VLOOKUP(C14, $A$9:$E$11, 4, FALSE)) / $B$5 ,1), 0 ) -> 9 | F14: =VLOOKUP(C14, $A$9:$E$11, 5, FALSE) -> 4 | G14: =IF( A14<=3, VLOOKUP(A14, 'Tabla anual'!$C$2:$D$4, 2, FALSE), IF(D14>=$B$6, 1, 0) ) -> 4 | H14: {=IF( E14=0, 0, IF( _xlfn.RANK.EQ(E14,$E$14:$E$23,0)<=3, INDEX('Tabla anual'!$F$2:$F$4, _xlfn.RANK.EQ(E14,$E$14:$E$23,0)), IF(E14>='Tabla anual'!$F$5, 1, 0) ) )} -> 4 | I14: =sum(F14:H14) -> 12
A15: 2 | B15: Vicky | C15: Celeste | D15: 62 | E15: =IFERROR( FLOOR( (D15 / VLOOKUP(C15, $A$9:$E$11, 4, FALSE)) / $B$5 ,1), 0 ) -> 4 | F15: =VLOOKUP(C15, $A$9:$E$11, 5, FALSE) -> 2 | G15: =IF( A15<=3, VLOOKUP(A15, 'Tabla anual'!$C$2:$D$4, 2, FALSE), IF(D15>=$B$6, 1, 0) ) -> 3 | H15: {=IF( E15=0, 0, IF( _xlfn.RANK.EQ(E15,$E$14:$E$23,0)<=3, INDEX('Tabla anual'!$F$2:$F$4, _xlfn.RANK.EQ(E15,$E$14:$E$23,0)), IF(E15>='Tabla anual'!$F$5, 1, 0) ) )} -> 2 | I15: =sum(F15:H15) -> 7
A16: 3 | B16: Lu | C16: Amarillo | D16: 57 | E16: =IFERROR( FLOOR( (D16 / VLOOKUP(C16, $A$9:$E$11, 4, FALSE)) / $B$5 ,1), 0 ) -> 3 | F16: =VLOOKUP(C16, $A$9:$E$11, 5, FALSE) -> 3 | G16: =IF( A16<=3, VLOOKUP(A16, 'Tabla anual'!$C$2:$D$4, 2, FALSE), IF(D16>=$B$6, 1, 0) ) -> 2 | H16: {=IF( E16=0, 0, IF( _xlfn.RANK.EQ(E16,$E$14:$E$23,0)<=3, INDEX('Tabla anual'!$F$2:$F$4, _xlfn.RANK.EQ(E16,$E$14:$E$23,0)), IF(E16>='Tabla anual'!$F$5, 1, 0) ) )} -> 1 | I16: =sum(F16:H16) -> 6
A17: 4 | B17: Chiqui | C17: Celeste | D17: 56 | E17: =IFERROR( FLOOR( (D17 / VLOOKUP(C17, $A$9:$E$11, 4, FALSE)) / $B$5 ,1), 0 ) -> 3 | F17: =VLOOKUP(C17, $A$9:$E$11, 5, FALSE) -> 2 | G17: =IF( A17<=3, VLOOKUP(A17, 'Tabla anual'!$C$2:$D$4, 2, FALSE), IF(D17>=$B$6, 1, 0) ) -> 1 | H17: {=IF( E17=0, 0, IF( _xlfn.RANK.EQ(E17,$E$14:$E$23,0)<=3, INDEX('Tabla anual'!$F$2:$F$4, _xlfn.RANK.EQ(E17,$E$14:$E$23,0)), IF(E17>='Tabla anual'!$F$5, 1, 0) ) )} -> 1 | I17: =sum(F17:H17) -> 4
A18: 5 | B18: Maru M | C18: Rojo | D18: 53 | E18: =IFERROR( FLOOR( (D18 / VLOOKUP(C18, $A$9:$E$11, 4, FALSE)) / $B$5 ,1), 0 ) -> 5 | F18: =VLOOKUP(C18, $A$9:$E$11, 5, FALSE) -> 4 | G18: =IF( A18<=3, VLOOKUP(A18, 'Tabla anual'!$C$2:$D$4, 2, FALSE), IF(D18>=$B$6, 1, 0) ) -> 1 | H18: {=IF( E18=0, 0, IF( _xlfn.RANK.EQ(E18,$E$14:$E$23,0)<=3, INDEX('Tabla anual'!$F$2:$F$4, _xlfn.RANK.EQ(E18,$E$14:$E$23,0)), IF(E18>='Tabla anual'!$F$5, 1, 0) ) )} -> 3 | I18: =sum(F18:H18) -> 8
A19: 6 | B19: Samy | C19: Amarillo | D19: 49 | E19: =IFERROR( FLOOR( (D19 / VLOOKUP(C19, $A$9:$E$11, 4, FALSE)) / $B$5 ,1), 0 ) -> 3 | F19: =VLOOKUP(C19, $A$9:$E$11, 5, FALSE) -> 3 | G19: =IF( A19<=3, VLOOKUP(A19, 'Tabla anual'!$C$2:$D$4, 2, FALSE), IF(D19>=$B$6, 1, 0) ) -> 1 | H19: {=IF( E19=0, 0, IF( _xlfn.RANK.EQ(E19,$E$14:$E$23,0)<=3, INDEX('Tabla anual'!$F$2:$F$4, _xlfn.RANK.EQ(E19,$E$14:$E$23,0)), IF(E19>='Tabla anual'!$F$5, 1, 0) ) )} -> 1 | I19: =sum(F19:H19) -> 5
A20: 7 | B20: Gio | C20: Amarillo | D20: 44 | E20: =IFERROR( FLOOR( (D20 / VLOOKUP(C20, $A$9:$E$11, 4, FALSE)) / $B$5 ,1), 0 ) -> 3 | F20: =VLOOKUP(C20, $A$9:$E$11, 5, FALSE) -> 3 | G20: =IF( A20<=3, VLOOKUP(A20, 'Tabla anual'!$C$2:$D$4, 2, FALSE), IF(D20>=$B$6, 1, 0) ) -> 0 | H20: {=IF( E20=0, 0, IF( _xlfn.RANK.EQ(E20,$E$14:$E$23,0)<=3, INDEX('Tabla anual'!$F$2:$F$4, _xlfn.RANK.EQ(E20,$E$14:$E$23,0)), IF(E20>='Tabla anual'!$F$5, 1, 0) ) )} -> 1 | I20: =sum(F20:H20) -> 4
A21: 8 | B21: Maru C | C21: Celeste | D21: 26 | E21: =IFERROR( FLOOR( (D21 / VLOOKUP(C21, $A$9:$E$11, 4, FALSE)) / $B$5 ,1), 0 ) -> 1 | F21: =VLOOKUP(C21, $A$9:$E$11, 5, FALSE) -> 2 | G21: =IF( A21<=3, VLOOKUP(A21, 'Tabla anual'!$C$2:$D$4, 2, FALSE), IF(D21>=$B$6, 1, 0) ) -> 0 | H21: {=IF( E21=0, 0, IF( _xlfn.RANK.EQ(E21,$E$14:$E$23,0)<=3, INDEX('Tabla anual'!$F$2:$F$4, _xlfn.RANK.EQ(E21,$E$14:$E$23,0)), IF(E21>='Tabla anual'!$F$5, 1, 0) ) )} -> 1 | I21: =sum(F21:H21) -> 3
A22: 9 | B22: Estela | C22: Celeste | D22: 6 | E22: =IFERROR( FLOOR( (D22 / VLOOKUP(C22, $A$9:$E$11, 4, FALSE)) / $B$5 ,1), 0 ) -> 0 | F22: =VLOOKUP(C22, $A$9:$E$11, 5, FALSE) -> 2 | G22: =IF( A22<=3, VLOOKUP(A22, 'Tabla anual'!$C$2:$D$4, 2, FALSE), IF(D22>=$B$6, 1, 0) ) -> 0 | H22: {=IF( E22=0, 0, IF( _xlfn.RANK.EQ(E22,$E$14:$E$23,0)<=3, INDEX('Tabla anual'!$F$2:$F$4, _xlfn.RANK.EQ(E22,$E$14:$E$23,0)), IF(E22>='Tabla anual'!$F$5, 1, 0) ) )} -> 0 | I22: =sum(F22:H22) -> 2
A23: 10 | B23: Nico | C23: Rojo | D23: 4 | E23: =IFERROR( FLOOR( (D23 / VLOOKUP(C23, $A$9:$E$11, 4, FALSE)) / $B$5 ,1), 0 ) -> 0 | F23: =VLOOKUP(C23, $A$9:$E$11, 5, FALSE) -> 4 | G23: =IF( A23<=3, VLOOKUP(A23, 'Tabla anual'!$C$2:$D$4, 2, FALSE), IF(D23>=$B$6, 1, 0) ) -> 0 | H23: {=IF( E23=0, 0, IF( _xlfn.RANK.EQ(E23,$E$14:$E$23,0)<=3, INDEX('Tabla anual'!$F$2:$F$4, _xlfn.RANK.EQ(E23,$E$14:$E$23,0)), IF(E23>='Tabla anual'!$F$5, 1, 0) ) )} -> 0 | I23: =sum(F23:H23) -> 4
A24: 11 | B24: Abi | D24: 0 | E24: =IFERROR( FLOOR( (D24 / VLOOKUP(C24, $A$9:$E$11, 4, FALSE)) / $B$5 ,1), 0 ) -> 0 | F24: 0 | G24: =IF( A24<=3, VLOOKUP(A24, 'Tabla anual'!$C$2:$D$4, 2, FALSE), IF(D24>=$B$6, 1, 0) ) -> 0 | H24: {=IF( E24=0, 0, IF( _xlfn.RANK.EQ(E24,$E$14:$E$23,0)<=3, INDEX('Tabla anual'!$F$2:$F$4, _xlfn.RANK.EQ(E24,$E$14:$E$23,0)), IF(E24>='Tabla anual'!$F$5, 1, 0) ) )} -> 0 | I24: =sum(F24:H24) -> 0

Sheet 212
A1: Objetivo del desafío | B1: Completar 25 tareas de investigacion
A2: Fecha de inicio | B2: 46006.917
A3: Fecha final oficial | B3: 46014.917
A4: Duración total (horas) | B4: =(B3-B2)*24 -> 192
A5: Ritmo oficial | B5: =75/B4 -> 0.390625
A6: Cantidad Media (cantidadxequipos)/participantes | B6: =(25*3)/11 -> 6.8181818
A8: Equipo | B8: Puesto | C8: Hora de finalización | D8: Horas totales | E8: Puntos
A9: Celeste | B9: 1 | C9: 46007.119 | D9: =(C9-$B$2)*24 -> 4.85 | E9: ='Tabla anual'!B2 -> 4
A10: Naranja | B10: 2 | C10: 46007.453 | D10: =(C10-$B$2)*24 -> 12.866667 | E10: ='Tabla anual'!B3 -> 3
A11: Amarillo | B11: 3 | C11: 46007.557 | D11: =(C11-$B$2)*24 -> 15.366667 | E11: ='Tabla anual'!B4 -> 2
A13: Posición | B13: Nombre | C13: Equipo | D13: Cantidad | E13: Plus Velocidad | F13: Puntos Equipo | G13: Puntos Cantidad | H13: Puntos Velocidad | I13: Total de Puntos
A14: 1 | B14: Maru C | C14: Celeste | D14: 16 | E14: =IFERROR( FLOOR( (D14 / VLOOKUP(C14, $A$9:$E$11, 4, FALSE)) / $B$5 ,1), 0 ) -> 8 | F14: =VLOOKUP(C14, $A$9:$E$11, 5, FALSE) -> 4 | G14: =IF( A14<=3, VLOOKUP(A14, 'Tabla anual'!$C$2:$D$4, 2, FALSE), IF(D14>=$B$6, 1, 0) ) -> 4 | H14: {=IF( E14=0, 0, IF( _xlfn.RANK.EQ(E14,$E$14:$E$24,0)<=3, INDEX('Tabla anual'!$F$2:$F$4, _xlfn.RANK.EQ(E14,$E$14:$E$24,0)), IF(E14>='Tabla anual'!$F$5, 1, 0) ) )} -> 4 | I14: =sum(F14:H14) -> 12
A15: 2 | B15: Nico | C15: Naranja | D15: 11 | E15: =IFERROR( FLOOR( (D15 / VLOOKUP(C15, $A$9:$E$11, 4, FALSE)) / $B$5 ,1), 0 ) -> 2 | F15: =VLOOKUP(C15, $A$9:$E$11, 5, FALSE) -> 3 | G15: =IF( A15<=3, VLOOKUP(A15, 'Tabla anual'!$C$2:$D$4, 2, FALSE), IF(D15>=$B$6, 1, 0) ) -> 3 | H15: {=IF( E15=0, 0, IF( _xlfn.RANK.EQ(E15,$E$14:$E$23,0)<=3, INDEX('Tabla anual'!$F$2:$F$4, _xlfn.RANK.EQ(E15,$E$14:$E$23,0)), IF(E15>='Tabla anual'!$F$5, 1, 0) ) )} -> 2 | I15: =sum(F15:H15) -> 8
A16: 3 | B16: Gio | C16: Amarillo | D16: 10 | E16: =IFERROR( FLOOR( (#REF! / VLOOKUP(#REF!, $A$9:$E$11, 4, FALSE)) / $B$5 ,1), 0 ) -> 0 | F16: =VLOOKUP(C16, $A$9:$E$11, 5, FALSE) -> 2 | G16: =IF( A16<=3, VLOOKUP(A16, 'Tabla anual'!$C$2:$D$4, 2, FALSE), IF(D16>=$B$6, 1, 0) ) -> 2 | H16: {=IF( E16=0, 0, IF( _xlfn.RANK.EQ(E16,$E$14:$E$23,0)<=3, INDEX('Tabla anual'!$F$2:$F$4, _xlfn.RANK.EQ(E16,$E$14:$E$23,0)), IF(E16>='Tabla anual'!$F$5, 1, 0) ) )} -> 0 | I16: =sum(F16:H16) -> 4
A17: 4 | B17: Facu | C17: Naranja | D17: 9 | E17: =IFERROR( FLOOR( (#REF! / VLOOKUP(#REF!, $A$9:$E$11, 4, FALSE)) / $B$5 ,1), 0 ) -> 0 | F17: =VLOOKUP(C17, $A$9:$E$11, 5, FALSE) -> 3 | G17: =IF( A17<=3, VLOOKUP(A17, 'Tabla anual'!$C$2:$D$4, 2, FALSE), IF(D17>=$B$6, 1, 0) ) -> 1 | H17: {=IF( E17=0, 0, IF( _xlfn.RANK.EQ(E17,$E$14:$E$23,0)<=3, INDEX('Tabla anual'!$F$2:$F$4, _xlfn.RANK.EQ(E17,$E$14:$E$23,0)), IF(E17>='Tabla anual'!$F$5, 1, 0) ) )} -> 0 | I17: =sum(F17:H17) -> 4
A18: 5 | B18: Lu | C18: Amarillo | D18: 9 | E18: =IFERROR( FLOOR( (#REF! / VLOOKUP(#REF!, $A$9:$E$11, 4, FALSE)) / $B$5 ,1), 0 ) -> 0 | F18: =VLOOKUP(C18, $A$9:$E$11, 5, FALSE) -> 2 | G18: =IF( A18<=3, VLOOKUP(A18, 'Tabla anual'!$C$2:$D$4, 2, FALSE), IF(D18>=$B$6, 1, 0) ) -> 1 | H18: {=IF( E18=0, 0, IF( _xlfn.RANK.EQ(E18,$E$14:$E$23,0)<=3, INDEX('Tabla anual'!$F$2:$F$4, _xlfn.RANK.EQ(E18,$E$14:$E$23,0)), IF(E18>='Tabla anual'!$F$5, 1, 0) ) )} -> 0 | I18: =sum(F18:H18) -> 3
A19: 6 | B19: Vicky | C19: Celeste | D19: 6 | E19: =IFERROR( FLOOR( (D19 / VLOOKUP(C19, $A$9:$E$11, 4, FALSE)) / $B$5 ,1), 0 ) -> 3 | F19: =VLOOKUP(C19, $A$9:$E$11, 5, FALSE) -> 4 | G19: =IF( A19<=3, VLOOKUP(A19, 'Tabla anual'!$C$2:$D$4, 2, FALSE), IF(D19>=$B$6, 1, 0) ) -> 0 | H19: {=IF( E19=0, 0, IF( _xlfn.RANK.EQ(E19,$E$14:$E$23,0)<=3, INDEX('Tabla anual'!$F$2:$F$4, _xlfn.RANK.EQ(E19,$E$14:$E$23,0)), IF(E19>='Tabla anual'!$F$5, 1, 0) ) )} -> 3 | I19: =sum(F19:H19) -> 7
A20: 7 | B20: Maru M | C20: Amarillo | D20: 6 | E20: =IFERROR( FLOOR( (D20 / VLOOKUP(C20, $A$9:$E$11, 4, FALSE)) / $B$5 ,1), 0 ) -> 0 | F20: =VLOOKUP(C20, $A$9:$E$11, 5, FALSE) -> 2 | G20: =IF( A20<=3, VLOOKUP(A20, 'Tabla anual'!$C$2:$D$4, 2, FALSE), IF(D20>=$B$6, 1, 0) ) -> 0 | H20: {=IF( E20=0, 0, IF( _xlfn.RANK.EQ(E20,$E$14:$E$23,0)<=3, INDEX('Tabla anual'!$F$2:$F$4, _xlfn.RANK.EQ(E20,$E$14:$E$23,0)), IF(E20>='Tabla anual'!$F$5, 1, 0) ) )} -> 0 | I20: =sum(F20:H20) -> 2
A21: 8 | B21: Samy | C21: Celeste | D21: 3 | E21: =IFERROR( FLOOR( (#REF! / VLOOKUP(#REF!, $A$9:$E$11, 4, FALSE)) / $B$5 ,1), 0 ) -> 0 | F21: =VLOOKUP(C21, $A$9:$E$11, 5, FALSE) -> 4 | G21: =IF( A21<=3, VLOOKUP(A21, 'Tabla anual'!$C$2:$D$4, 2, FALSE), IF(D21>=$B$6, 1, 0) ) -> 0 | H21: {=IF( E21=0, 0, IF( _xlfn.RANK.EQ(E21,$E$14:$E$23,0)<=3, INDEX('Tabla anual'!$F$2:$F$4, _xlfn.RANK.EQ(E21,$E$14:$E$23,0)), IF(E21>='Tabla anual'!$F$5, 1, 0) ) )} -> 0 | I21: =sum(F21:H21) -> 4
A22: 9 | B22: Abi | C22: Naranja | D22: 3 | E22: =IFERROR( FLOOR( (#REF! / VLOOKUP(#REF!, $A$9:$E$11, 4, FALSE)) / $B$5 ,1), 0 ) -> 0 | F22: =VLOOKUP(C22, $A$9:$E$11, 5, FALSE) -> 3 | G22: =IF( A22<=3, VLOOKUP(A22, 'Tabla anual'!$C$2:$D$4, 2, FALSE), IF(D22>=$B$6, 1, 0) ) -> 0 | H22: {=IF( E22=0, 0, IF( _xlfn.RANK.EQ(E22,$E$14:$E$23,0)<=3, INDEX('Tabla anual'!$F$2:$F$4, _xlfn.RANK.EQ(E22,$E$14:$E$23,0)), IF(E22>='Tabla anual'!$F$5, 1, 0) ) )} -> 0 | I22: =sum(F22:H22) -> 3
A23: 10 | B23: Chiqui | C23: Naranja | D23: 2 | E23: =IFERROR( FLOOR( (#REF! / VLOOKUP(#REF!, $A$9:$E$11, 4, FALSE)) / $B$5 ,1), 0 ) -> 0 | F23: =VLOOKUP(C23, $A$9:$E$11, 5, FALSE) -> 3 | G23: =IF( A23<=3, VLOOKUP(A23, 'Tabla anual'!$C$2:$D$4, 2, FALSE), IF(D23>=$B$6, 1, 0) ) -> 0 | H23: {=IF( E23=0, 0, IF( _xlfn.RANK.EQ(E23,$E$14:$E$23,0)<=3, INDEX('Tabla anual'!$F$2:$F$4, _xlfn.RANK.EQ(E23,$E$14:$E$23,0)), IF(E23>='Tabla anual'!$F$5, 1, 0) ) )} -> 0 | I23: =sum(F23:H23) -> 3
A24: 11 | B24: Estela | C24: Amarillo | D24: 0 | E24: =IFERROR( FLOOR( (D24 / VLOOKUP(C24, $A$9:$E$11, 4, FALSE)) / $B$5 ,1), 0 ) -> 0 | F24: =VLOOKUP(C24, $A$9:$E$11, 5, FALSE) -> 2 | G24: =IF( A24<=3, VLOOKUP(A24, 'Tabla anual'!$C$2:$D$4, 2, FALSE), IF(D24>=$B$6, 1, 0) ) -> 0 | H24: {=IF( E24=0, 0, IF( _xlfn.RANK.EQ(E24,$E$14:$E$23,0)<=3, INDEX('Tabla anual'!$F$2:$F$4, _xlfn.RANK.EQ(E24,$E$14:$E$23,0)), IF(E24>='Tabla anual'!$F$5, 1, 0) ) )} -> 0 | I24: =sum(F24:H24) -> 2

Sheet 312
A1: Objetivo del desafío | B1: Explora 30 kms
A2: Fecha de inicio | B2: 46013
A3: Fecha final oficial | B3: 46020
A4: Duración total (horas) | B4: =(B3-B2)*24 -> 168
A5: Ritmo oficial | B5: =75/B4 -> 0.44642857
A6: Cantidad Media (cantidadxequipos)/participantes | B6: =(30*3)/11 -> 8.1818182
A8: Equipo | B8: Puesto | C8: Hora de finalización | D8: Horas totales | E8: Puntos
A9: Amarillo | B9: 1 | C9: 46014.988 | D9: =(C9-$B$2)*24 -> 47.716667 | E9: ='Tabla anual'!B2 -> 4
A10: Naranja | B10: 2 | C10: 46015.511 | D10: =(C10-$B$2)*24 -> 60.266667 | E10: ='Tabla anual'!B3 -> 3
A11: Celeste | B11: 3 | C11: 46016.897 | D11: =(C11-$B$2)*24 -> 93.533333 | E11: ='Tabla anual'!B4 -> 2
A13: Posición | B13: Nombre | C13: Equipo | D13: Cantidad | E13: Plus Velocidad | F13: Puntos Equipo | G13: Puntos Cantidad | H13: Puntos Velocidad | I13: Total de Puntos
A14: 1 | B14: Samy | C14: Amarillo | D14: 18 | E14: =IFERROR( FLOOR( (D14 / VLOOKUP(C14, $A$9:$E$11, 4, FALSE)) / $B$5 ,1), 0 ) -> 0 | F14: =VLOOKUP(C14, $A$9:$E$11, 5, FALSE) -> 4 | G14: =IF( A14<=3, VLOOKUP(A14, 'Tabla anual'!$C$2:$D$4, 2, FALSE), IF(D14>=$B$6, 1, 0) ) -> 4 | H14: {=IF( E14=0, 0, IF( _xlfn.RANK.EQ(E14,$E$14:$E$24,0)<=3, INDEX('Tabla anual'!$F$2:$F$4, _xlfn.RANK.EQ(E14,$E$14:$E$24,0)), IF(E14>='Tabla anual'!$F$5, 1, 0) ) )} -> 0 | I14: =sum(F14:H14) -> 8
A15: 2 | B15: Facu | C15: Naranja | D15: 13 | E15: =IFERROR( FLOOR( (D15 / VLOOKUP(C15, $A$9:$E$11, 4, FALSE)) / $B$5 ,1), 0 ) -> 0 | F15: =VLOOKUP(C15, $A$9:$E$11, 5, FALSE) -> 3 | G15: =IF( A15<=3, VLOOKUP(A15, 'Tabla anual'!$C$2:$D$4, 2, FALSE), IF(D15>=$B$6, 1, 0) ) -> 3 | H15: {=IF( E15=0, 0, IF( _xlfn.RANK.EQ(E15,$E$14:$E$23,0)<=3, INDEX('Tabla anual'!$F$2:$F$4, _xlfn.RANK.EQ(E15,$E$14:$E$23,0)), IF(E15>='Tabla anual'!$F$5, 1, 0) ) )} -> 0 | I15: =sum(F15:H15) -> 6
A16: 3 | B16: Estela | C16: Celeste | D16: 11 | E16: =IFERROR( FLOOR( (#REF! / VLOOKUP(#REF!, $A$9:$E$11, 4, FALSE)) / $B$5 ,1), 0 ) -> 0 | F16: =VLOOKUP(C16, $A$9:$E$11, 5, FALSE) -> 2 | G16: =IF( A16<=3, VLOOKUP(A16, 'Tabla anual'!$C$2:$D$4, 2, FALSE), IF(D16>=$B$6, 1, 0) ) -> 2 | H16: {=IF( E16=0, 0, IF( _xlfn.RANK.EQ(E16,$E$14:$E$23,0)<=3, INDEX('Tabla anual'!$F$2:$F$4, _xlfn.RANK.EQ(E16,$E$14:$E$23,0)), IF(E16>='Tabla anual'!$F$5, 1, 0) ) )} -> 0 | I16: =sum(F16:H16) -> 4
A17: 4 | B17: Maru M | C17: Celeste | D17: 9 | E17: =IFERROR( FLOOR( (#REF! / VLOOKUP(#REF!, $A$9:$E$11, 4, FALSE)) / $B$5 ,1), 0 ) -> 0 | F17: =VLOOKUP(C17, $A$9:$E$11, 5, FALSE) -> 2 | G17: =IF( A17<=3, VLOOKUP(A17, 'Tabla anual'!$C$2:$D$4, 2, FALSE), IF(D17>=$B$6, 1, 0) ) -> 1 | H17: {=IF( E17=0, 0, IF( _xlfn.RANK.EQ(E17,$E$14:$E$23,0)<=3, INDEX('Tabla anual'!$F$2:$F$4, _xlfn.RANK.EQ(E17,$E$14:$E$23,0)), IF(E17>='Tabla anual'!$F$5, 1, 0) ) )} -> 0 | I17: =sum(F17:H17) -> 3
A18: 5 | B18: Lu | C18: Naranja | D18: 7 | E18: =IFERROR( FLOOR( (#REF! / VLOOKUP(#REF!, $A$9:$E$11, 4, FALSE)) / $B$5 ,1), 0 ) -> 0 | F18: =VLOOKUP(C18, $A$9:$E$11, 5, FALSE) -> 3 | G18: =IF( A18<=3, VLOOKUP(A18, 'Tabla anual'!$C$2:$D$4, 2, FALSE), IF(D18>=$B$6, 1, 0) ) -> 0 | H18: {=IF( E18=0, 0, IF( _xlfn.RANK.EQ(E18,$E$14:$E$23,0)<=3, INDEX('Tabla anual'!$F$2:$F$4, _xlfn.RANK.EQ(E18,$E$14:$E$23,0)), IF(E18>='Tabla anual'!$F$5, 1, 0) ) )} -> 0 | I18: =sum(F18:H18) -> 3
A19: 6 | B19: Gio | C19: Celeste | D19: 6 | E19: =IFERROR( FLOOR( (D19 / VLOOKUP(C19, $A$9:$E$11, 4, FALSE)) / $B$5 ,1), 0 ) -> 0 | F19: =VLOOKUP(C19, $A$9:$E$11, 5, FALSE) -> 2 | G19: =IF( A19<=3, VLOOKUP(A19, 'Tabla anual'!$C$2:$D$4, 2, FALSE), IF(D19>=$B$6, 1, 0) ) -> 0 | H19: {=IF( E19=0, 0, IF( _xlfn.RANK.EQ(E19,$E$14:$E$23,0)<=3, INDEX('Tabla anual'!$F$2:$F$4, _xlfn.RANK.EQ(E19,$E$14:$E$23,0)), IF(E19>='Tabla anual'!$F$5, 1, 0) ) )} -> 0 | I19: =sum(F19:H19) -> 2
A20: 7 | B20: Chiqui | C20: Amarillo | D20: 6 | E20: =IFERROR( FLOOR( (#REF! / VLOOKUP(#REF!, $A$9:$E$11, 4, FALSE)) / $B$5 ,1), 0 ) -> 0 | F20: =VLOOKUP(C20, $A$9:$E$11, 5, FALSE) -> 4 | G20: =IF( A20<=3, VLOOKUP(A20, 'Tabla anual'!$C$2:$D$4, 2, FALSE), IF(D20>=$B$6, 1, 0) ) -> 0 | H20: {=IF( E20=0, 0, IF( _xlfn.RANK.EQ(E20,$E$14:$E$23,0)<=3, INDEX('Tabla anual'!$F$2:$F$4, _xlfn.RANK.EQ(E20,$E$14:$E$23,0)), IF(E20>='Tabla anual'!$F$5, 1, 0) ) )} -> 0 | I20: =sum(F20:H20) -> 4
A21: 8 | B21: Vicky | C21: Amarillo | D21: 6 | E21: =IFERROR( FLOOR( (#REF! / VLOOKUP(#REF!, $A$9:$E$11, 4, FALSE)) / $B$5 ,1), 0 ) -> 0 | F21: =VLOOKUP(C21, $A$9:$E$11, 5, FALSE) -> 4 | G21: =IF( A21<=3, VLOOKUP(A21, 'Tabla anual'!$C$2:$D$4, 2, FALSE), IF(D21>=$B$6, 1, 0) ) -> 0 | H21: {=IF( E21=0, 0, IF( _xlfn.RANK.EQ(E21,$E$14:$E$23,0)<=3, INDEX('Tabla anual'!$F$2:$F$4, _xlfn.RANK.EQ(E21,$E$14:$E$23,0)), IF(E21>='Tabla anual'!$F$5, 1, 0) ) )} -> 0 | I21: =sum(F21:H21) -> 4
A22: 9 | B22: Abi | C22: Naranja | D22: 5 | E22: =IFERROR( FLOOR( (#REF! / VLOOKUP(#REF!, $A$9:$E$11, 4, FALSE)) / $B$5 ,1), 0 ) -> 0 | F22: =VLOOKUP(C22, $A$9:$E$11, 5, FALSE) -> 3 | G22: =IF( A22<=3, VLOOKUP(A22, 'Tabla anual'!$C$2:$D$4, 2, FALSE), IF(D22>=$B$6, 1, 0) ) -> 0 | H22: {=IF( E22=0, 0, IF( _xlfn.RANK.EQ(E22,$E$14:$E$23,0)<=3, INDEX('Tabla anual'!$F$2:$F$4, _xlfn.RANK.EQ(E22,$E$14:$E$23,0)), IF(E22>='Tabla anual'!$F$5, 1, 0) ) )} -> 0 | I22: =sum(F22:H22) -> 3
A23: 10 | B23: Nico | C23: Naranja | D23: 5 | E23: =IFERROR( FLOOR( (#REF! / VLOOKUP(#REF!, $A$9:$E$11, 4, FALSE)) / $B$5 ,1), 0 ) -> 0 | F23: =VLOOKUP(C23, $A$9:$E$11, 5, FALSE) -> 3 | G23: =IF( A23<=3, VLOOKUP(A23, 'Tabla anual'!$C$2:$D$4, 2, FALSE), IF(D23>=$B$6, 1, 0) ) -> 0 | H23: {=IF( E23=0, 0, IF( _xlfn.RANK.EQ(E23,$E$14:$E$23,0)<=3, INDEX('Tabla anual'!$F$2:$F$4, _xlfn.RANK.EQ(E23,$E$14:$E$23,0)), IF(E23>='Tabla anual'!$F$5, 1, 0) ) )} -> 0 | I23: =sum(F23:H23) -> 3
A24: 11 | B24: Maru C | C24: Celeste | D24: 4 | E24: =IFERROR( FLOOR( (D24 / VLOOKUP(C24, $A$9:$E$11, 4, FALSE)) / $B$5 ,1), 0 ) -> 0 | F24: =VLOOKUP(C24, $A$9:$E$11, 5, FALSE) -> 2 | G24: =IF( A24<=3, VLOOKUP(A24, 'Tabla anual'!$C$2:$D$4, 2, FALSE), IF(D24>=$B$6, 1, 0) ) -> 0 | H24: {=IF( E24=0, 0, IF( _xlfn.RANK.EQ(E24,$E$14:$E$23,0)<=3, INDEX('Tabla anual'!$F$2:$F$4, _xlfn.RANK.EQ(E24,$E$14:$E$23,0)), IF(E24>='Tabla anual'!$F$5, 1, 0) ) )} -> 0 | I24: =sum(F24:H24) -> 2

Sheet 412
A1: Objetivo del desafío | B1: Atrapa 500 pokemones
A2: Fecha de inicio | B2: 46020.917
A3: Fecha final oficial | B3: 46027.917
A4: Duración total (horas) | B4: =(B3-B2)*24 -> 168
A5: Ritmo oficial | B5: =75/B4 -> 0.44642857
A6: Cantidad Media (cantidadxequipos)/participantes | B6: =(500*3)/11 -> 136.36364
A8: Equipo | B8: Puesto | C8: Hora de finalización | D8: Horas totales | E8: Puntos
A9: Amarillo | B9: 1 | C9: 46021.512 | D9: =(C9-$B$2)*24 -> 14.283333 | E9: ='Tabla anual'!B2 -> 4
A10: Naranja | B10: 2 | C10: 46021.619 | D10: =(C10-$B$2)*24 -> 16.866667 | E10: ='Tabla anual'!B3 -> 3
A11: Celeste | B11: 3 | C11: 46025 | D11: =(C11-$B$2)*24 -> 98 | E11: ='Tabla anual'!B4 -> 2
A13: Posición | B13: Nombre | C13: Equipo | D13: Cantidad | E13: Plus Velocidad | F13: Puntos Equipo | G13: Puntos Cantidad | H13: Puntos Velocidad | I13: Total de Puntos
A14: 1 | B14: Facu | C14: Celeste | D14: 400 | E14: =IFERROR( FLOOR( (D14 / VLOOKUP(C14, $A$9:$E$11, 4, FALSE)) / $B$5 ,1), 0 ) -> 9 | F14: =VLOOKUP(C14, $A$9:$E$11, 5, FALSE) -> 2 | G14: =IF( A14<=3, VLOOKUP(A14, 'Tabla anual'!$C$2:$D$4, 2, FALSE), IF(D14>=$B$6, 1, 0) ) -> 4 | H14: {=IF( E14=0, 0, IF( _xlfn.RANK.EQ(E14,$E$14:$E$24,0)<=3, INDEX('Tabla anual'!$F$2:$F$4, _xlfn.RANK.EQ(E14,$E$14:$E$24,0)), IF(E14>='Tabla anual'!$F$5, 1, 0) ) )} -> 1 | I14: =sum(F14:H14) -> 7
A15: 2 | B15: Vicky | C15: Amarillo | D15: 248 | E15: =IFERROR( FLOOR( (D15 / VLOOKUP(C15, $A$9:$E$11, 4, FALSE)) / $B$5 ,1), 0 ) -> 38 | F15: =VLOOKUP(C15, $A$9:$E$11, 5, FALSE) -> 4 | G15: =IF( A15<=3, VLOOKUP(A15, 'Tabla anual'!$C$2:$D$4, 2, FALSE), IF(D15>=$B$6, 1, 0) ) -> 3 | H15: {=IF( E15=0, 0, IF( _xlfn.RANK.EQ(E15,$E$14:$E$23,0)<=3, INDEX('Tabla anual'!$F$2:$F$4, _xlfn.RANK.EQ(E15,$E$14:$E$23,0)), IF(E15>='Tabla anual'!$F$5, 1, 0) ) )} -> 4 | I15: =sum(F15:H15) -> 11
A16: 3 | B16: Nico | C16: Naranja | D16: 245 | E16: =IFERROR( FLOOR( (D16 / VLOOKUP(C16, $A$9:$E$11, 4, FALSE)) / $B$5 ,1), 0 ) -> 32 | F16: =VLOOKUP(C16, $A$9:$E$11, 5, FALSE) -> 3 | G16: =IF( A16<=3, VLOOKUP(A16, 'Tabla anual'!$C$2:$D$4, 2, FALSE), IF(D16>=$B$6, 1, 0) ) -> 2 | H16: {=IF( E16=0, 0, IF( _xlfn.RANK.EQ(E16,$E$14:$E$23,0)<=3, INDEX('Tabla anual'!$F$2:$F$4, _xlfn.RANK.EQ(E16,$E$14:$E$23,0)), IF(E16>='Tabla anual'!$F$5, 1, 0) ) )} -> 3 | I16: =sum(F16:H16) -> 8
A17: 4 | B17: Lu | C17: Naranja | D17: 139 | E17: =IFERROR( FLOOR( (D17 / VLOOKUP(C17, $A$9:$E$11, 4, FALSE)) / $B$5 ,1), 0 ) -> 18 | F17: =VLOOKUP(C17, $A$9:$E$11, 5, FALSE) -> 3 | G17: =IF( A17<=3, VLOOKUP(A17, 'Tabla anual'!$C$2:$D$4, 2, FALSE), IF(D17>=$B$6, 1, 0) ) -> 1 | H17: {=IF( E17=0, 0, IF( _xlfn.RANK.EQ(E17,$E$14:$E$23,0)<=3, INDEX('Tabla anual'!$F$2:$F$4, _xlfn.RANK.EQ(E17,$E$14:$E$23,0)), IF(E17>='Tabla anual'!$F$5, 1, 0) ) )} -> 1 | I17: =sum(F17:H17) -> 5
A18: 5 | B18: Maru M | C18: Amarillo | D18: 127 | E18: =IFERROR( FLOOR( (D18 / VLOOKUP(C18, $A$9:$E$11, 4, FALSE)) / $B$5 ,1), 0 ) -> 19 | F18: =VLOOKUP(C18, $A$9:$E$11, 5, FALSE) -> 4 | G18: =IF( A18<=3, VLOOKUP(A18, 'Tabla anual'!$C$2:$D$4, 2, FALSE), IF(D18>=$B$6, 1, 0) ) -> 0 | H18: {=IF( E18=0, 0, IF( _xlfn.RANK.EQ(E18,$E$14:$E$23,0)<=3, INDEX('Tabla anual'!$F$2:$F$4, _xlfn.RANK.EQ(E18,$E$14:$E$23,0)), IF(E18>='Tabla anual'!$F$5, 1, 0) ) )} -> 2 | I18: =sum(F18:H18) -> 6
A19: 6 | B19: Maru C | C19: Amarillo | D19: 125 | E19: =IFERROR( FLOOR( (D19 / VLOOKUP(C19, $A$9:$E$11, 4, FALSE)) / $B$5 ,1), 0 ) -> 19 | F19: =VLOOKUP(C19, $A$9:$E$11, 5, FALSE) -> 4 | G19: =IF( A19<=3, VLOOKUP(A19, 'Tabla anual'!$C$2:$D$4, 2, FALSE), IF(D19>=$B$6, 1, 0) ) -> 0 | H19: {=IF( E19=0, 0, IF( _xlfn.RANK.EQ(E19,$E$14:$E$23,0)<=3, INDEX('Tabla anual'!$F$2:$F$4, _xlfn.RANK.EQ(E19,$E$14:$E$23,0)), IF(E19>='Tabla anual'!$F$5, 1, 0) ) )} -> 2 | I19: =sum(F19:H19) -> 6
A20: 7 | B20: Gio | C20: Naranja | D20: 96 | E20: =IFERROR( FLOOR( (D20 / VLOOKUP(C20, $A$9:$E$11, 4, FALSE)) / $B$5 ,1), 0 ) -> 12 | F20: =VLOOKUP(C20, $A$9:$E$11, 5, FALSE) -> 3 | G20: =IF( A20<=3, VLOOKUP(A20, 'Tabla anual'!$C$2:$D$4, 2, FALSE), IF(D20>=$B$6, 1, 0) ) -> 0 | H20: {=IF( E20=0, 0, IF( _xlfn.RANK.EQ(E20,$E$14:$E$23,0)<=3, INDEX('Tabla anual'!$F$2:$F$4, _xlfn.RANK.EQ(E20,$E$14:$E$23,0)), IF(E20>='Tabla anual'!$F$5, 1, 0) ) )} -> 1 | I20: =sum(F20:H20) -> 4
A21: 8 | B21: Chiqui | C21: Celeste | D21: 52 | E21: =IFERROR( FLOOR( (D21 / VLOOKUP(C21, $A$9:$E$11, 4, FALSE)) / $B$5 ,1), 0 ) -> 1 | F21: =VLOOKUP(C21, $A$9:$E$11, 5, FALSE) -> 2 | G21: =IF( A21<=3, VLOOKUP(A21, 'Tabla anual'!$C$2:$D$4, 2, FALSE), IF(D21>=$B$6, 1, 0) ) -> 0 | H21: {=IF( E21=0, 0, IF( _xlfn.RANK.EQ(E21,$E$14:$E$23,0)<=3, INDEX('Tabla anual'!$F$2:$F$4, _xlfn.RANK.EQ(E21,$E$14:$E$23,0)), IF(E21>='Tabla anual'!$F$5, 1, 0) ) )} -> 1 | I21: =sum(F21:H21) -> 3
A22: 9 | B22: Abi | C22: Celeste | D22: 48 | E22: =IFERROR( FLOOR( (D22 / VLOOKUP(C22, $A$9:$E$11, 4, FALSE)) / $B$5 ,1), 0 ) -> 1 | F22: =VLOOKUP(C22, $A$9:$E$11, 5, FALSE) -> 2 | G22: =IF( A22<=3, VLOOKUP(A22, 'Tabla anual'!$C$2:$D$4, 2, FALSE), IF(D22>=$B$6, 1, 0) ) -> 0 | H22: {=IF( E22=0, 0, IF( _xlfn.RANK.EQ(E22,$E$14:$E$23,0)<=3, INDEX('Tabla anual'!$F$2:$F$4, _xlfn.RANK.EQ(E22,$E$14:$E$23,0)), IF(E22>='Tabla anual'!$F$5, 1, 0) ) )} -> 1 | I22: =sum(F22:H22) -> 3
A23: 10 | B23: Samy | C23: Naranja | D23: 20 | E23: =IFERROR( FLOOR( (D24 / VLOOKUP(C24, $A$9:$E$11, 4, FALSE)) / $B$5 ,1), 0 ) -> 0 | F23: =VLOOKUP(C23, $A$9:$E$11, 5, FALSE) -> 3 | G23: =IF( A23<=3, VLOOKUP(A23, 'Tabla anual'!$C$2:$D$4, 2, FALSE), IF(D23>=$B$6, 1, 0) ) -> 0 | H23: {=IF( E23=0, 0, IF( _xlfn.RANK.EQ(E23,$E$14:$E$23,0)<=3, INDEX('Tabla anual'!$F$2:$F$4, _xlfn.RANK.EQ(E23,$E$14:$E$23,0)), IF(E23>='Tabla anual'!$F$5, 1, 0) ) )} -> 0 | I23: =sum(F23:H23) -> 3
A24: 11 | B24: Estela | C24: Amarillo | D24: 0 | E24: =IFERROR( FLOOR( (#REF! / VLOOKUP(#REF!, $A$9:$E$11, 4, FALSE)) / $B$5 ,1), 0 ) -> 0 | F24: =VLOOKUP(C24, $A$9:$E$11, 5, FALSE) -> 4 | G24: =IF( A24<=3, VLOOKUP(A24, 'Tabla anual'!$C$2:$D$4, 2, FALSE), IF(D24>=$B$6, 1, 0) ) -> 0 | H24: {=IF( E24=0, 0, IF( _xlfn.RANK.EQ(E24,$E$14:$E$23,0)<=3, INDEX('Tabla anual'!$F$2:$F$4, _xlfn.RANK.EQ(E24,$E$14:$E$23,0)), IF(E24>='Tabla anual'!$F$5, 1, 0) ) )} -> 0 | I24: =sum(F24:H24) -> 4

Sheet 11
A1: Objetivo del desafío | B1: Girar 150 Pokeparadas
A2: Fecha de inicio | B2: 46027.917
A3: Fecha final oficial | B3: 46034.917
A4: Duración total (horas) | B4: =(B3-B2)*24 -> 168
A5: Ritmo oficial | B5: =75/B4 -> 0.44642857
A6: Cantidad Media (cantidadxequipos)/participantes | B6: =(150*3)/11 -> 40.909091
A8: Equipo | B8: Puesto | C8: Hora de finalización | D8: Horas totales | E8: Puntos
A9: Celeste | B9: 1 | C9: 46028.033 | D9: =(C9-$B$2)*24 -> 2.8 | E9: ='Tabla anual'!B2 -> 4
A10: Naranja | B10: 2 | C10: 46028.419 | D10: =(C10-$B$2)*24 -> 12.066667 | E10: ='Tabla anual'!B3 -> 3
A11: Amarillo | B11: 3 | C11: 46028.612 | D11: =(C11-$B$2)*24 -> 16.683333 | E11: ='Tabla anual'!B4 -> 2
A13: Posición | B13: Nombre | C13: Equipo | D13: Cantidad | E13: Plus Velocidad | F13: Puntos Equipo | G13: Puntos Cantidad | H13: Puntos Velocidad | I13: Total de Puntos
A14: 1 | B14: Chiqui | C14: Celeste | D14: 75 | E14: =IFERROR( FLOOR( (D14 / VLOOKUP(C14, $A$9:$E$11, 4, FALSE)) / $B$5 ,1), 0 ) -> 59 | F14: =VLOOKUP(C14, $A$9:$E$11, 5, FALSE) -> 4 | G14: =IFERROR(__xludf.DUMMYFUNCTION("IF( D14="""", """", LET( cant, D14, rango, FILTER($D$14:$D$24, $D$14:$D$24<>""""), puestos, SORT(UNIQUE(rango), 1, FALSE), puesto, MATCH(cant, puestos, 0), IF( puesto<=3, VLOOKUP(puesto, 'Tabla anual'!$C$2:$D$4, 2, FA"&"LSE), IF(cant>=$B$6, 1, 0) ) ) )"),4.0) -> 4 | H14: {=IF( E14=0, 0, IF( _xlfn.RANK.EQ(E14,$E$14:$E$24,0)<=3, INDEX('Tabla anual'!$F$2:$F$4, _xlfn.RANK.EQ(E14,$E$14:$E$24,0)), IF(E14>='Tabla anual'!$F$5, 1, 0) ) )} -> 4 | I14: =sum(F14:H14) -> 12
A15: 2 | B15: Abi | C15: Celeste | D15: 75 | E15: =IFERROR( FLOOR( (D15 / VLOOKUP(C15, $A$9:$E$11, 4, FALSE)) / $B$5 ,1), 0 ) -> 59 | F15: =VLOOKUP(C15, $A$9:$E$11, 5, FALSE) -> 4 | G15: =IFERROR(__xludf.DUMMYFUNCTION("IF( D15="""", """", LET( cant, D15, rango, FILTER($D$14:$D$24, $D$14:$D$24<>""""), puestos, SORT(UNIQUE(rango), 1, FALSE), puesto, MATCH(cant, puestos, 0), IF( puesto<=3, VLOOKUP(puesto, 'Tabla anual'!$C$2:$D$4, 2, FA"&"LSE), IF(cant>=$B$6, 1, 0) ) ) )"),4.0) -> 4 | H15: {=IF( E15=0, 0, IF( _xlfn.RANK.EQ(E15,$E$14:$E$23,0)<=3, INDEX('Tabla anual'!$F$2:$F$4, _xlfn.RANK.EQ(E15,$E$14:$E$23,0)), IF(E15>='Tabla anual'!$F$5, 1, 0) ) )} -> 4 | I15: =sum(F15:H15) -> 12
A16: 3 | B16: Vicky | C16: Amarillo | D16: 74 | E16: =IFERROR( FLOOR( (D16 / VLOOKUP(C16, $A$9:$E$11, 4, FALSE)) / $B$5 ,1), 0 ) -> 9 | F16: =VLOOKUP(C16, $A$9:$E$11, 5, FALSE) -> 2 | G16: =IFERROR(__xludf.DUMMYFUNCTION("IF( D16="""", """", LET( cant, D16, rango, FILTER($D$14:$D$24, $D$14:$D$24<>""""), puestos, SORT(UNIQUE(rango), 1, FALSE), puesto, MATCH(cant, puestos, 0), IF( puesto<=3, VLOOKUP(puesto, 'Tabla anual'!$C$2:$D$4, 2, FA"&"LSE), IF(cant>=$B$6, 1, 0) ) ) )"),3.0) -> 3 | H16: {=IF( E16=0, 0, IF( _xlfn.RANK.EQ(E16,$E$14:$E$23,0)<=3, INDEX('Tabla anual'!$F$2:$F$4, _xlfn.RANK.EQ(E16,$E$14:$E$23,0)), IF(E16>='Tabla anual'!$F$5, 1, 0) ) )} -> 1 | I16: =sum(F16:H16) -> 6
A17: 4 | B17: Maru M | C17: Naranja | D17: 67 | E17: =IFERROR( FLOOR( (D17 / VLOOKUP(C17, $A$9:$E$11, 4, FALSE)) / $B$5 ,1), 0 ) -> 12 | F17: =VLOOKUP(C17, $A$9:$E$11, 5, FALSE) -> 3 | G17: =IFERROR(__xludf.DUMMYFUNCTION("IF( D17="""", """", LET( cant, D17, rango, FILTER($D$14:$D$24, $D$14:$D$24<>""""), puestos, SORT(UNIQUE(rango), 1, FALSE), puesto, MATCH(cant, puestos, 0), IF( puesto<=3, VLOOKUP(puesto, 'Tabla anual'!$C$2:$D$4, 2, FA"&"LSE), IF(cant>=$B$6, 1, 0) ) ) )"),2.0) -> 2 | H17: {=IF( E17=0, 0, IF( _xlfn.RANK.EQ(E17,$E$14:$E$23,0)<=3, INDEX('Tabla anual'!$F$2:$F$4, _xlfn.RANK.EQ(E17,$E$14:$E$23,0)), IF(E17>='Tabla anual'!$F$5, 1, 0) ) )} -> 2 | I17: =sum(F17:H17) -> 7
A18: 5 | B18: Nico | C18: Naranja | D18: 41 | E18: =IFERROR( FLOOR( (D18 / VLOOKUP(C18, $A$9:$E$11, 4, FALSE)) / $B$5 ,1), 0 ) -> 7 | F18: =VLOOKUP(C18, $A$9:$E$11, 5, FALSE) -> 3 | G18: =IFERROR(__xludf.DUMMYFUNCTION("IF( D18="""", """", LET( cant, D18, rango, FILTER($D$14:$D$24, $D$14:$D$24<>""""), puestos, SORT(UNIQUE(rango), 1, FALSE), puesto, MATCH(cant, puestos, 0), IF( puesto<=3, VLOOKUP(puesto, 'Tabla anual'!$C$2:$D$4, 2, FA"&"LSE), IF(cant>=$B$6, 1, 0) ) ) )"),1.0) -> 1 | H18: {=IF( E18=0, 0, IF( _xlfn.RANK.EQ(E18,$E$14:$E$23,0)<=3, INDEX('Tabla anual'!$F$2:$F$4, _xlfn.RANK.EQ(E18,$E$14:$E$23,0)), IF(E18>='Tabla anual'!$F$5, 1, 0) ) )} -> 1 | I18: =sum(F18:H18) -> 5
A19: 6 | B19: Maru C | C19: Naranja | D19: 40 | E19: =IFERROR( FLOOR( (D19 / VLOOKUP(C19, $A$9:$E$11, 4, FALSE)) / $B$5 ,1), 0 ) -> 7 | F19: =VLOOKUP(C19, $A$9:$E$11, 5, FALSE) -> 3 | G19: =IFERROR(__xludf.DUMMYFUNCTION("IF( D19="""", """", LET( cant, D19, rango, FILTER($D$14:$D$24, $D$14:$D$24<>""""), puestos, SORT(UNIQUE(rango), 1, FALSE), puesto, MATCH(cant, puestos, 0), IF( puesto<=3, VLOOKUP(puesto, 'Tabla anual'!$C$2:$D$4, 2, FA"&"LSE), IF(cant>=$B$6, 1, 0) ) ) )"),0.0) -> 0 | H19: {=IF( E19=0, 0, IF( _xlfn.RANK.EQ(E19,$E$14:$E$23,0)<=3, INDEX('Tabla anual'!$F$2:$F$4, _xlfn.RANK.EQ(E19,$E$14:$E$23,0)), IF(E19>='Tabla anual'!$F$5, 1, 0) ) )} -> 1 | I19: =sum(F19:H19) -> 4
A20: 7 | B20: Lu | C20: Amarillo | D20: 39 | E20: =IFERROR( FLOOR( (D20 / VLOOKUP(C20, $A$9:$E$11, 4, FALSE)) / $B$5 ,1), 0 ) -> 5 | F20: =VLOOKUP(C20, $A$9:$E$11, 5, FALSE) -> 2 | G20: =IFERROR(__xludf.DUMMYFUNCTION("IF( D20="""", """", LET( cant, D20, rango, FILTER($D$14:$D$24, $D$14:$D$24<>""""), puestos, SORT(UNIQUE(rango), 1, FALSE), puesto, MATCH(cant, puestos, 0), IF( puesto<=3, VLOOKUP(puesto, 'Tabla anual'!$C$2:$D$4, 2, FA"&"LSE), IF(cant>=$B$6, 1, 0) ) ) )"),0.0) -> 0 | H20: {=IF( E20=0, 0, IF( _xlfn.RANK.EQ(E20,$E$14:$E$23,0)<=3, INDEX('Tabla anual'!$F$2:$F$4, _xlfn.RANK.EQ(E20,$E$14:$E$23,0)), IF(E20>='Tabla anual'!$F$5, 1, 0) ) )} -> 1 | I20: =sum(F20:H20) -> 3
A21: 8 | B21: Gio | C21: Amarillo | D21: 21 | E21: =IFERROR( FLOOR( (D21 / VLOOKUP(C21, $A$9:$E$11, 4, FALSE)) / $B$5 ,1), 0 ) -> 2 | F21: =VLOOKUP(C21, $A$9:$E$11, 5, FALSE) -> 2 | G21: =IFERROR(__xludf.DUMMYFUNCTION("IF( D21="""", """", LET( cant, D21, rango, FILTER($D$14:$D$24, $D$14:$D$24<>""""), puestos, SORT(UNIQUE(rango), 1, FALSE), puesto, MATCH(cant, puestos, 0), IF( puesto<=3, VLOOKUP(puesto, 'Tabla anual'!$C$2:$D$4, 2, FA"&"LSE), IF(cant>=$B$6, 1, 0) ) ) )"),0.0) -> 0 | H21: {=IF( E21=0, 0, IF( _xlfn.RANK.EQ(E21,$E$14:$E$23,0)<=3, INDEX('Tabla anual'!$F$2:$F$4, _xlfn.RANK.EQ(E21,$E$14:$E$23,0)), IF(E21>='Tabla anual'!$F$5, 1, 0) ) )} -> 1 | I21: =sum(F21:H21) -> 3
A22: 9 | B22: Estela | C22: Amarillo | D22: 16 | E22: =IFERROR( FLOOR( (D22 / VLOOKUP(C22, $A$9:$E$11, 4, FALSE)) / $B$5 ,1), 0 ) -> 2 | F22: =VLOOKUP(C22, $A$9:$E$11, 5, FALSE) -> 2 | G22: =IFERROR(__xludf.DUMMYFUNCTION("IF( D22="""", """", LET( cant, D22, rango, FILTER($D$14:$D$24, $D$14:$D$24<>""""), puestos, SORT(UNIQUE(rango), 1, FALSE), puesto, MATCH(cant, puestos, 0), IF( puesto<=3, VLOOKUP(puesto, 'Tabla anual'!$C$2:$D$4, 2, FA"&"LSE), IF(cant>=$B$6, 1, 0) ) ) )"),0.0) -> 0 | H22: {=IF( E22=0, 0, IF( _xlfn.RANK.EQ(E22,$E$14:$E$23,0)<=3, INDEX('Tabla anual'!$F$2:$F$4, _xlfn.RANK.EQ(E22,$E$14:$E$23,0)), IF(E22>='Tabla anual'!$F$5, 1, 0) ) )} -> 1 | I22: =sum(F22:H22) -> 3
A23: 10 | B23: Samy | C23: Naranja | D23: 2 | E23: =IFERROR( FLOOR( (D24 / VLOOKUP(C24, $A$9:$E$11, 4, FALSE)) / $B$5 ,1), 0 ) -> 0 | F23: =VLOOKUP(C23, $A$9:$E$11, 5, FALSE) -> 3 | G23: =IFERROR(__xludf.DUMMYFUNCTION("IF( D23="""", """", LET( cant, D23, rango, FILTER($D$14:$D$24, $D$14:$D$24<>""""), puestos, SORT(UNIQUE(rango), 1, FALSE), puesto, MATCH(cant, puestos, 0), IF( puesto<=3, VLOOKUP(puesto, 'Tabla anual'!$C$2:$D$4, 2, FA"&"LSE), IF(cant>=$B$6, 1, 0) ) ) )"),0.0) -> 0 | H23: {=IF( E23=0, 0, IF( _xlfn.RANK.EQ(E23,$E$14:$E$23,0)<=3, INDEX('Tabla anual'!$F$2:$F$4, _xlfn.RANK.EQ(E23,$E$14:$E$23,0)), IF(E23>='Tabla anual'!$F$5, 1, 0) ) )} -> 0 | I23: =sum(F23:H23) -> 3
A24: 11 | B24: Facu | D24: 0 | E24: =IFERROR( FLOOR( (#REF! / VLOOKUP(#REF!, $A$9:$E$11, 4, FALSE)) / $B$5 ,1), 0 ) -> 0 | F24: 0 | G24: =IFERROR(__xludf.DUMMYFUNCTION("IF( D24="""", """", LET( cant, D24, rango, FILTER($D$14:$D$24, $D$14:$D$24<>""""), puestos, SORT(UNIQUE(rango), 1, FALSE), puesto, MATCH(cant, puestos, 0), IF( puesto<=3, VLOOKUP(puesto, 'Tabla anual'!$C$2:$D$4, 2, FA"&"LSE), IF(cant>=$B$6, 1, 0) ) ) )"),0.0) -> 0 | H24: {=IF( E24=0, 0, IF( _xlfn.RANK.EQ(E24,$E$14:$E$23,0)<=3, INDEX('Tabla anual'!$F$2:$F$4, _xlfn.RANK.EQ(E24,$E$14:$E$23,0)), IF(E24>='Tabla anual'!$F$5, 1, 0) ) )} -> 0 | I24: =sum(F24:H24) -> 0

Sheet 21
A1: Objetivo del desafío | B1: 25 tareas de investigacion
A2: Fecha de inicio | B2: 46035.417
A3: Fecha final oficial | B3: 46042.917
A4: Duración total (horas) | B4: =(B3-B2)*24 -> 180
A5: Ritmo oficial | B5: =75/B4 -> 0.41666667
A6: Cantidad Media (cantidadxequipos)/participantes | B6: =(25*3)/11 -> 6.8181818
A8: Equipo | B8: Puesto | C8: Hora de finalización | D8: Horas totales | E8: Puntos
A9: Naranja | B9: 1 | C9: 46035.562 | D9: =(C9-$B$2)*24 -> 3.5 | E9: ='Tabla anual'!B2 -> 4
A10: Amarillo | B10: 2 | C10: 46035.625 | D10: =(C10-$B$2)*24 -> 5 | E10: ='Tabla anual'!B3 -> 3
A11: Celeste | B11: 3 | C11: 46035.81 | D11: =(C11-$B$2)*24 -> 9.45 | E11: ='Tabla anual'!B4 -> 2
A13: Posición | B13: Nombre | C13: Equipo | D13: Cantidad | E13: Plus Velocidad | F13: Puntos Equipo | G13: Puntos Cantidad | H13: Puntos Velocidad | I13: Total de Puntos
A14: 1 | B14: Maru M | C14: Celeste | D14: 13 | E14: =IFERROR( FLOOR( (D14 / VLOOKUP(C14, $A$9:$E$11, 4, FALSE)) / $B$5 ,1), 0 ) -> 3 | F14: =VLOOKUP(C14, $A$9:$E$11, 5, FALSE) -> 2 | G14: =IFERROR(__xludf.DUMMYFUNCTION("IF( D14="""", """", LET( cant, D14, rango, FILTER($D$14:$D$24, $D$14:$D$24<>""""), puestos, SORT(UNIQUE(rango), 1, FALSE), puesto, MATCH(cant, puestos, 0), IF( puesto<=3, VLOOKUP(puesto, 'Tabla anual'!$C$2:$D$4, 2, FA"&"LSE), IF(cant>=$B$6, 1, 0) ) ) )"),4.0) -> 4 | H14: {=IF( E14=0, 0, IF( _xlfn.RANK.EQ(E14,$E$14:$E$24,0)<=3, INDEX('Tabla anual'!$F$2:$F$4, _xlfn.RANK.EQ(E14,$E$14:$E$24,0)), IF(E14>='Tabla anual'!$F$5, 1, 0) ) )} -> 1 | I14: =sum(F14:H14) -> 7
A15: 2 | B15: Gio | C15: Celeste | D15: 12 | E15: =IFERROR( FLOOR( (D15 / VLOOKUP(C15, $A$9:$E$11, 4, FALSE)) / $B$5 ,1), 0 ) -> 3 | F15: =VLOOKUP(C15, $A$9:$E$11, 5, FALSE) -> 2 | G15: =IFERROR(__xludf.DUMMYFUNCTION("IF( D15="""", """", LET( cant, D15, rango, FILTER($D$14:$D$24, $D$14:$D$24<>""""), puestos, SORT(UNIQUE(rango), 1, FALSE), puesto, MATCH(cant, puestos, 0), IF( puesto<=3, VLOOKUP(puesto, 'Tabla anual'!$C$2:$D$4, 2, FA"&"LSE), IF(cant>=$B$6, 1, 0) ) ) )"),3.0) -> 3 | H15: {=IF( E15=0, 0, IF( _xlfn.RANK.EQ(E15,$E$14:$E$23,0)<=3, INDEX('Tabla anual'!$F$2:$F$4, _xlfn.RANK.EQ(E15,$E$14:$E$23,0)), IF(E15>='Tabla anual'!$F$5, 1, 0) ) )} -> 1 | I15: =sum(F15:H15) -> 6
A16: 3 | B16: Nico | C16: Amarillo | D16: 12 | E16: =IFERROR( FLOOR( (D16 / VLOOKUP(C16, $A$9:$E$11, 4, FALSE)) / $B$5 ,1), 0 ) -> 5 | F16: =VLOOKUP(C16, $A$9:$E$11, 5, FALSE) -> 3 | G16: =IFERROR(__xludf.DUMMYFUNCTION("IF( D16="""", """", LET( cant, D16, rango, FILTER($D$14:$D$24, $D$14:$D$24<>""""), puestos, SORT(UNIQUE(rango), 1, FALSE), puesto, MATCH(cant, puestos, 0), IF( puesto<=3, VLOOKUP(puesto, 'Tabla anual'!$C$2:$D$4, 2, FA"&"LSE), IF(cant>=$B$6, 1, 0) ) ) )"),3.0) -> 3 | H16: {=IF( E16=0, 0, IF( _xlfn.RANK.EQ(E16,$E$14:$E$23,0)<=3, INDEX('Tabla anual'!$F$2:$F$4, _xlfn.RANK.EQ(E16,$E$14:$E$23,0)), IF(E16>='Tabla anual'!$F$5, 1, 0) ) )} -> 3 | I16: =sum(F16:H16) -> 9
A17: 4 | B17: Vicky | C17: Naranja | D17: 10 | E17: =IFERROR( FLOOR( (D17 / VLOOKUP(C17, $A$9:$E$11, 4, FALSE)) / $B$5 ,1), 0 ) -> 6 | F17: =VLOOKUP(C17, $A$9:$E$11, 5, FALSE) -> 4 | G17: =IFERROR(__xludf.DUMMYFUNCTION("IF( D17="""", """", LET( cant, D17, rango, FILTER($D$14:$D$24, $D$14:$D$24<>""""), puestos, SORT(UNIQUE(rango), 1, FALSE), puesto, MATCH(cant, puestos, 0), IF( puesto<=3, VLOOKUP(puesto, 'Tabla anual'!$C$2:$D$4, 2, FA"&"LSE), IF(cant>=$B$6, 1, 0) ) ) )"),2.0) -> 2 | H17: {=IF( E17=0, 0, IF( _xlfn.RANK.EQ(E17,$E$14:$E$23,0)<=3, INDEX('Tabla anual'!$F$2:$F$4, _xlfn.RANK.EQ(E17,$E$14:$E$23,0)), IF(E17>='Tabla anual'!$F$5, 1, 0) ) )} -> 4 | I17: =sum(F17:H17) -> 10
A18: 5 | B18: Chiqui | C18: Amarillo | D18: 9 | E18: =IFERROR( FLOOR( (D18 / VLOOKUP(C18, $A$9:$E$11, 4, FALSE)) / $B$5 ,1), 0 ) -> 4 | F18: =VLOOKUP(C18, $A$9:$E$11, 5, FALSE) -> 3 | G18: =IFERROR(__xludf.DUMMYFUNCTION("IF( D18="""", """", LET( cant, D18, rango, FILTER($D$14:$D$24, $D$14:$D$24<>""""), puestos, SORT(UNIQUE(rango), 1, FALSE), puesto, MATCH(cant, puestos, 0), IF( puesto<=3, VLOOKUP(puesto, 'Tabla anual'!$C$2:$D$4, 2, FA"&"LSE), IF(cant>=$B$6, 1, 0) ) ) )"),1.0) -> 1 | H18: {=IF( E18=0, 0, IF( _xlfn.RANK.EQ(E18,$E$14:$E$23,0)<=3, INDEX('Tabla anual'!$F$2:$F$4, _xlfn.RANK.EQ(E18,$E$14:$E$23,0)), IF(E18>='Tabla anual'!$F$5, 1, 0) ) )} -> 2 | I18: =sum(F18:H18) -> 6
A19: 6 | B19: Lu | C19: Naranja | D19: 7 | E19: =IFERROR( FLOOR( (D19 / VLOOKUP(C19, $A$9:$E$11, 4, FALSE)) / $B$5 ,1), 0 ) -> 4 | F19: =VLOOKUP(C19, $A$9:$E$11, 5, FALSE) -> 4 | G19: =IFERROR(__xludf.DUMMYFUNCTION("IF( D19="""", """", LET( cant, D19, rango, FILTER($D$14:$D$24, $D$14:$D$24<>""""), puestos, SORT(UNIQUE(rango), 1, FALSE), puesto, MATCH(cant, puestos, 0), IF( puesto<=3, VLOOKUP(puesto, 'Tabla anual'!$C$2:$D$4, 2, FA"&"LSE), IF(cant>=$B$6, 1, 0) ) ) )"),1.0) -> 1 | H19: {=IF( E19=0, 0, IF( _xlfn.RANK.EQ(E19,$E$14:$E$23,0)<=3, INDEX('Tabla anual'!$F$2:$F$4, _xlfn.RANK.EQ(E19,$E$14:$E$23,0)), IF(E19>='Tabla anual'!$F$5, 1, 0) ) )} -> 2 | I19: =sum(F19:H19) -> 7
A20: 7 | B20: Samy | C20: Naranja | D20: 6 | E20: =IFERROR( FLOOR( (D20 / VLOOKUP(C20, $A$9:$E$11, 4, FALSE)) / $B$5 ,1), 0 ) -> 4 | F20: =VLOOKUP(C20, $A$9:$E$11, 5, FALSE) -> 4 | G20: =IFERROR(__xludf.DUMMYFUNCTION("IF( D20="""", """", LET( cant, D20, rango, FILTER($D$14:$D$24, $D$14:$D$24<>""""), puestos, SORT(UNIQUE(rango), 1, FALSE), puesto, MATCH(cant, puestos, 0), IF( puesto<=3, VLOOKUP(puesto, 'Tabla anual'!$C$2:$D$4, 2, FA"&"LSE), IF(cant>=$B$6, 1, 0) ) ) )"),0.0) -> 0 | H20: {=IF( E20=0, 0, IF( _xlfn.RANK.EQ(E20,$E$14:$E$23,0)<=3, INDEX('Tabla anual'!$F$2:$F$4, _xlfn.RANK.EQ(E20,$E$14:$E$23,0)), IF(E20>='Tabla anual'!$F$5, 1, 0) ) )} -> 2 | I20: =sum(F20:H20) -> 6
A21: 8 | B21: Estela | C21: Amarillo | D21: 4 | E21: =IFERROR( FLOOR( (D21 / VLOOKUP(C21, $A$9:$E$11, 4, FALSE)) / $B$5 ,1), 0 ) -> 1 | F21: =VLOOKUP(C21, $A$9:$E$11, 5, FALSE) -> 3 | G21: =IFERROR(__xludf.DUMMYFUNCTION("IF( D21="""", """", LET( cant, D21, rango, FILTER($D$14:$D$24, $D$14:$D$24<>""""), puestos, SORT(UNIQUE(rango), 1, FALSE), puesto, MATCH(cant, puestos, 0), IF( puesto<=3, VLOOKUP(puesto, 'Tabla anual'!$C$2:$D$4, 2, FA"&"LSE), IF(cant>=$B$6, 1, 0) ) ) )"),0.0) -> 0 | H21: {=IF( E21=0, 0, IF( _xlfn.RANK.EQ(E21,$E$14:$E$23,0)<=3, INDEX('Tabla anual'!$F$2:$F$4, _xlfn.RANK.EQ(E21,$E$14:$E$23,0)), IF(E21>='Tabla anual'!$F$5, 1, 0) ) )} -> 1 | I21: =sum(F21:H21) -> 4
A22: 9 | B22: Abi | C22: Naranja | D22: 2 | E22: =IFERROR( FLOOR( (D22 / VLOOKUP(C22, $A$9:$E$11, 4, FALSE)) / $B$5 ,1), 0 ) -> 1 | F22: =VLOOKUP(C22, $A$9:$E$11, 5, FALSE) -> 4 | G22: =IFERROR(__xludf.DUMMYFUNCTION("IF( D22="""", """", LET( cant, D22, rango, FILTER($D$14:$D$24, $D$14:$D$24<>""""), puestos, SORT(UNIQUE(rango), 1, FALSE), puesto, MATCH(cant, puestos, 0), IF( puesto<=3, VLOOKUP(puesto, 'Tabla anual'!$C$2:$D$4, 2, FA"&"LSE), IF(cant>=$B$6, 1, 0) ) ) )"),0.0) -> 0 | H22: {=IF( E22=0, 0, IF( _xlfn.RANK.EQ(E22,$E$14:$E$23,0)<=3, INDEX('Tabla anual'!$F$2:$F$4, _xlfn.RANK.EQ(E22,$E$14:$E$23,0)), IF(E22>='Tabla anual'!$F$5, 1, 0) ) )} -> 1 | I22: =sum(F22:H22) -> 5
A23: 10 | B23: Maru C | C23: Celeste | D23: 0 | E23: =IFERROR( FLOOR( (D23 / VLOOKUP(C23, $A$9:$E$11, 4, FALSE)) / $B$5 ,1), 0 ) -> 0 | F23: =VLOOKUP(C23, $A$9:$E$11, 5, FALSE) -> 2 | G23: =IFERROR(__xludf.DUMMYFUNCTION("IF( D23="""", """", LET( cant, D23, rango, FILTER($D$14:$D$24, $D$14:$D$24<>""""), puestos, SORT(UNIQUE(rango), 1, FALSE), puesto, MATCH(cant, puestos, 0), IF( puesto<=3, VLOOKUP(puesto, 'Tabla anual'!$C$2:$D$4, 2, FA"&"LSE), IF(cant>=$B$6, 1, 0) ) ) )"),0.0) -> 0 | H23: {=IF( E23=0, 0, IF( _xlfn.RANK.EQ(E23,$E$14:$E$23,0)<=3, INDEX('Tabla anual'!$F$2:$F$4, _xlfn.RANK.EQ(E23,$E$14:$E$23,0)), IF(E23>='Tabla anual'!$F$5, 1, 0) ) )} -> 0 | I23: =sum(F23:H23) -> 2
A24: 11 | B24: Facu | C24: Amarillo | D24: 0 | E24: =IFERROR( FLOOR( (D24 / VLOOKUP(C24, $A$9:$E$11, 4, FALSE)) / $B$5 ,1), 0 ) -> 0 | F24: =VLOOKUP(C24, $A$9:$E$11, 5, FALSE) -> 3 | G24: =IFERROR(__xludf.DUMMYFUNCTION("IF( D24="""", """", LET( cant, D24, rango, FILTER($D$14:$D$24, $D$14:$D$24<>""""), puestos, SORT(UNIQUE(rango), 1, FALSE), puesto, MATCH(cant, puestos, 0), IF( puesto<=3, VLOOKUP(puesto, 'Tabla anual'!$C$2:$D$4, 2, FA"&"LSE), IF(cant>=$B$6, 1, 0) ) ) )"),0.0) -> 0 | H24: {=IF( E24=0, 0, IF( _xlfn.RANK.EQ(E24,$E$14:$E$23,0)<=3, INDEX('Tabla anual'!$F$2:$F$4, _xlfn.RANK.EQ(E24,$E$14:$E$23,0)), IF(E24>='Tabla anual'!$F$5, 1, 0) ) )} -> 0 | I24: =sum(F24:H24) -> 3
H37: =D16+D18+D21 -> 25

Sheet 31
A1: Objetivo del desafío | B1: Camina 30 km
A2: Fecha de inicio | B2: 46042.417
A3: Fecha final oficial | B3: 46048.917
A4: Duración total (horas) | B4: =(B3-B2)*24 -> 156
A5: Ritmo oficial | B5: =75/B4 -> 0.48076923
A6: Cantidad Media (cantidadxequipos)/participantes | B6: =(30*3)/11 -> 8.1818182
A8: Equipo | B8: Puesto | C8: Hora de finalización | D8: Horas totales | E8: Puntos
A9: Celeste | B9: 1 | C9: 46043.54 | D9: =(C9-$B$2)*24 -> 26.966667 | E9: ='Tabla anual'!B2 -> 4
A10: Amarillo | B10: 2 | C10: 46043.779 | D10: =(C10-$B$2)*24 -> 32.7 | E10: ='Tabla anual'!B3 -> 3
A11: Naranja | B11: 3 | C11: 46043.881 | D11: =(C11-$B$2)*24 -> 35.15 | E11: ='Tabla anual'!B4 -> 2
A13: Posición | B13: Nombre | C13: Equipo | D13: Cantidad | E13: Plus Velocidad | F13: Puntos Equipo | G13: Puntos Cantidad | H13: Puntos Velocidad | I13: Total de Puntos
A14: 1 | B14: Gio | C14: Amarillo | D14: 15 | E14: =IFERROR( FLOOR( (D14 / VLOOKUP(C14, $A$9:$E$11, 4, FALSE)) / $B$5 ,1), 0 ) -> 0 | F14: =VLOOKUP(C14, $A$9:$E$11, 5, FALSE) -> 3 | G14: =IFERROR(__xludf.DUMMYFUNCTION("IF( D14="""", """", LET( cant, D14, rango, FILTER($D$14:$D$24, $D$14:$D$24<>""""), puestos, SORT(UNIQUE(rango), 1, FALSE), puesto, MATCH(cant, puestos, 0), IF( puesto<=3, VLOOKUP(puesto, 'Tabla anual'!$C$2:$D$4, 2, FA"&"LSE), IF(cant>=$B$6, 1, 0) ) ) )"),4.0) -> 4 | H14: {=IF( E14=0, 0, IF( _xlfn.RANK.EQ(E14,$E$14:$E$24,0)<=3, INDEX('Tabla anual'!$F$2:$F$4, _xlfn.RANK.EQ(E14,$E$14:$E$24,0)), IF(E14>='Tabla anual'!$F$5, 1, 0) ) )} -> 0 | I14: =sum(F14:H14) -> 7
A15: 2 | B15: Samy | C15: Naranja | D15: =17-2-1 -> 14 | E15: =IFERROR( FLOOR( (#REF! / VLOOKUP(#REF!, $A$9:$E$11, 4, FALSE)) / $B$5 ,1), 0 ) -> 0 | F15: =VLOOKUP(C15, $A$9:$E$11, 5, FALSE) -> 2 | G15: =IFERROR(__xludf.DUMMYFUNCTION("IF( D15="""", """", LET( cant, D15, rango, FILTER($D$14:$D$24, $D$14:$D$24<>""""), puestos, SORT(UNIQUE(rango), 1, FALSE), puesto, MATCH(cant, puestos, 0), IF( puesto<=3, VLOOKUP(puesto, 'Tabla anual'!$C$2:$D$4, 2, FA"&"LSE), IF(cant>=$B$6, 1, 0) ) ) )"),3.0) -> 3 | H15: {=IF( E15=0, 0, IF( _xlfn.RANK.EQ(E15,$E$14:$E$24,0)<=3, INDEX('Tabla anual'!$F$2:$F$4, _xlfn.RANK.EQ(E15,$E$14:$E$24,0)), IF(E15>='Tabla anual'!$F$5, 1, 0) ) )} -> 0 | I15: =sum(F15:H15) -> 5
A16: 3 | B16: Lu | C16: Celeste | D16: 14 | E16: =IFERROR( FLOOR( (#REF! / VLOOKUP(#REF!, $A$9:$E$11, 4, FALSE)) / $B$5 ,1), 0 ) -> 0 | F16: =VLOOKUP(C16, $A$9:$E$11, 5, FALSE) -> 4 | G16: =IFERROR(__xludf.DUMMYFUNCTION("IF( D16="""", """", LET( cant, D16, rango, FILTER($D$14:$D$24, $D$14:$D$24<>""""), puestos, SORT(UNIQUE(rango), 1, FALSE), puesto, MATCH(cant, puestos, 0), IF( puesto<=3, VLOOKUP(puesto, 'Tabla anual'!$C$2:$D$4, 2, FA"&"LSE), IF(cant>=$B$6, 1, 0) ) ) )"),3.0) -> 3 | H16: {=IF( E16=0, 0, IF( _xlfn.RANK.EQ(E16,$E$14:$E$24,0)<=3, INDEX('Tabla anual'!$F$2:$F$4, _xlfn.RANK.EQ(E16,$E$14:$E$24,0)), IF(E16>='Tabla anual'!$F$5, 1, 0) ) )} -> 0 | I16: =sum(F16:H16) -> 7
A17: 4 | B17: Maru M | C17: Amarillo | D17: 10 | E17: =IFERROR( FLOOR( (#REF! / VLOOKUP(#REF!, $A$9:$E$11, 4, FALSE)) / $B$5 ,1), 0 ) -> 0 | F17: =VLOOKUP(C17, $A$9:$E$11, 5, FALSE) -> 3 | G17: =IFERROR(__xludf.DUMMYFUNCTION("IF( D17="""", """", LET( cant, D17, rango, FILTER($D$14:$D$24, $D$14:$D$24<>""""), puestos, SORT(UNIQUE(rango), 1, FALSE), puesto, MATCH(cant, puestos, 0), IF( puesto<=3, VLOOKUP(puesto, 'Tabla anual'!$C$2:$D$4, 2, FA"&"LSE), IF(cant>=$B$6, 1, 0) ) ) )"),2.0) -> 2 | H17: {=IF( E17=0, 0, IF( _xlfn.RANK.EQ(E17,$E$14:$E$24,0)<=3, INDEX('Tabla anual'!$F$2:$F$4, _xlfn.RANK.EQ(E17,$E$14:$E$24,0)), IF(E17>='Tabla anual'!$F$5, 1, 0) ) )} -> 0 | I17: =sum(F17:H17) -> 5
A18: 5 | B18: Chiqui | C18: Celeste | D18: 9 | E18: =IFERROR( FLOOR( (#REF! / VLOOKUP(#REF!, $A$9:$E$11, 4, FALSE)) / $B$5 ,1), 0 ) -> 0 | F18: =VLOOKUP(C18, $A$9:$E$11, 5, FALSE) -> 4 | G18: =IFERROR(__xludf.DUMMYFUNCTION("IF( D18="""", """", LET( cant, D18, rango, FILTER($D$14:$D$24, $D$14:$D$24<>""""), puestos, SORT(UNIQUE(rango), 1, FALSE), puesto, MATCH(cant, puestos, 0), IF( puesto<=3, VLOOKUP(puesto, 'Tabla anual'!$C$2:$D$4, 2, FA"&"LSE), IF(cant>=$B$6, 1, 0) ) ) )"),1.0) -> 1 | H18: {=IF( E18=0, 0, IF( _xlfn.RANK.EQ(E18,$E$14:$E$24,0)<=3, INDEX('Tabla anual'!$F$2:$F$4, _xlfn.RANK.EQ(E18,$E$14:$E$24,0)), IF(E18>='Tabla anual'!$F$5, 1, 0) ) )} -> 0 | I18: =sum(F18:H18) -> 5
A19: 6 | B19: Estela | C19: Naranja | D19: 9 | E19: =IFERROR( FLOOR( (#REF! / VLOOKUP(#REF!, $A$9:$E$11, 4, FALSE)) / $B$5 ,1), 0 ) -> 0 | F19: =VLOOKUP(C19, $A$9:$E$11, 5, FALSE) -> 2 | G19: =IFERROR(__xludf.DUMMYFUNCTION("IF( D19="""", """", LET( cant, D19, rango, FILTER($D$14:$D$24, $D$14:$D$24<>""""), puestos, SORT(UNIQUE(rango), 1, FALSE), puesto, MATCH(cant, puestos, 0), IF( puesto<=3, VLOOKUP(puesto, 'Tabla anual'!$C$2:$D$4, 2, FA"&"LSE), IF(cant>=$B$6, 1, 0) ) ) )"),1.0) -> 1 | H19: {=IF( E19=0, 0, IF( _xlfn.RANK.EQ(E19,$E$14:$E$24,0)<=3, INDEX('Tabla anual'!$F$2:$F$4, _xlfn.RANK.EQ(E19,$E$14:$E$24,0)), IF(E19>='Tabla anual'!$F$5, 1, 0) ) )} -> 0 | I19: =sum(F19:H19) -> 3
A20: 7 | B20: Vicky | C20: Celeste | D20: 7 | E20: =IFERROR( FLOOR( (D20 / VLOOKUP(C20, $A$9:$E$11, 4, FALSE)) / $B$5 ,1), 0 ) -> 0 | F20: =VLOOKUP(C20, $A$9:$E$11, 5, FALSE) -> 4 | G20: =IFERROR(__xludf.DUMMYFUNCTION("IF( D20="""", """", LET( cant, D20, rango, FILTER($D$14:$D$24, $D$14:$D$24<>""""), puestos, SORT(UNIQUE(rango), 1, FALSE), puesto, MATCH(cant, puestos, 0), IF( puesto<=3, VLOOKUP(puesto, 'Tabla anual'!$C$2:$D$4, 2, FA"&"LSE), IF(cant>=$B$6, 1, 0) ) ) )"),0.0) -> 0 | H20: {=IF( E20=0, 0, IF( _xlfn.RANK.EQ(E20,$E$14:$E$24,0)<=3, INDEX('Tabla anual'!$F$2:$F$4, _xlfn.RANK.EQ(E20,$E$14:$E$24,0)), IF(E20>='Tabla anual'!$F$5, 1, 0) ) )} -> 0 | I20: =sum(F20:H20) -> 4
A21: 8 | B21: Nico | C21: Naranja | D21: 6 | E21: =IFERROR( FLOOR( (#REF! / VLOOKUP(#REF!, $A$9:$E$11, 4, FALSE)) / $B$5 ,1), 0 ) -> 0 | F21: =VLOOKUP(C21, $A$9:$E$11, 5, FALSE) -> 2 | G21: =IFERROR(__xludf.DUMMYFUNCTION("IF( D21="""", """", LET( cant, D21, rango, FILTER($D$14:$D$24, $D$14:$D$24<>""""), puestos, SORT(UNIQUE(rango), 1, FALSE), puesto, MATCH(cant, puestos, 0), IF( puesto<=3, VLOOKUP(puesto, 'Tabla anual'!$C$2:$D$4, 2, FA"&"LSE), IF(cant>=$B$6, 1, 0) ) ) )"),0.0) -> 0 | H21: {=IF( E21=0, 0, IF( _xlfn.RANK.EQ(E21,$E$14:$E$24,0)<=3, INDEX('Tabla anual'!$F$2:$F$4, _xlfn.RANK.EQ(E21,$E$14:$E$24,0)), IF(E21>='Tabla anual'!$F$5, 1, 0) ) )} -> 0 | I21: =sum(F21:H21) -> 2
